Workbook

Sheet 测试总览
A2: 前后台联合测试执行记录 第八轮
A3: 2026年9月28日；承接第七轮并保留历史通过项。部分验证仍计“暂时测不了”，不等同完成验收。
A5: 检查项总数 | B5: 已通过 | C5: 有问题 | D5: 暂时测不了 | E5: 还没测 | F5: 不适用 | G5: 已执行比例 | H5: 通过比例
A6: =COUNTA(测试清单!$A$6:$A$157) -> 152 | B6: =COUNTIF(测试清单!$F$6:$F$157,"通过") -> 33 | C6: =COUNTIF(测试清单!$F$6:$F$157,"有问题") -> 9 | D6: =COUNTIF(测试清单!$F$6:$F$157,"暂时测不了") -> 107 | E6: =COUNTIF(测试清单!$F$6:$F$157,"还没测") -> 0 | F6: =COUNTIF(测试清单!$F$6:$F$157,"不适用") -> 3 | G6: =IF(A6-F6=0,"不适用",(B6+C6)/(A6-F6)) -> 0.28187919 | H6: =IF(B6+C6=0,"尚未执行",B6/(B6+C6)) -> 0.78571429
A8: 模块检查和整体流程都要验收
A9: 主清单152项：通过33、有问题9、暂时测不了107、不适用3。已补齐只读/第二操作员、MQTT目标和鸟类风险；完成并发、响应丢失、证据预览及协议分类等分支。
A10: 完整联合验收尚未完成。12:10固定后端版本1718项：通过1702、失败13、错误3、跳过0；12:43新版本设备定向43项全通过，分开计数。页面连接中断，双页长稳仅有69.3分钟有效采样；通知/设备回执及处罚接收方仍缺。
A12: 测试模块 | B12: 项数 | C12: 通过 | D12: 有问题 | E12: 暂时测不了 | F12: 还没测 | G12: 不适用 | H12: 已执行比例
A13: 登录和账号权限 | B13: =COUNTIF(测试清单!$B$6:$B$157,A13) -> 12 | C13: =COUNTIFS(测试清单!$B$6:$B$157,A13,测试清单!$F$6:$F$157,"通过") -> 4 | D13: =COUNTIFS(测试清单!$B$6:$B$157,A13,测试清单!$F$6:$F$157,"有问题") -> 1 | E13: =COUNTIFS(测试清单!$B$6:$B$157,A13,测试清单!$F$6:$F$157,"暂时测不了") -> 6 | F13: =COUNTIFS(测试清单!$B$6:$B$157,A13,测试清单!$F$6:$F$157,"还没测") -> 0 | G13: =COUNTIFS(测试清单!$B$6:$B$157,A13,测试清单!$F$6:$F$157,"不适用") -> 1 | H13: =IF(B13-G13=0,"不适用",(C13+D13)/(B13-G13)) -> 0.45454545
A14: 融合感知 | B14: =COUNTIF(测试清单!$B$6:$B$157,A14) -> 10 | C14: =COUNTIFS(测试清单!$B$6:$B$157,A14,测试清单!$F$6:$F$157,"通过") -> 2 | D14: =COUNTIFS(测试清单!$B$6:$B$157,A14,测试清单!$F$6:$F$157,"有问题") -> 1 | E14: =COUNTIFS(测试清单!$B$6:$B$157,A14,测试清单!$F$6:$F$157,"暂时测不了") -> 7 | F14: =COUNTIFS(测试清单!$B$6:$B$157,A14,测试清单!$F$6:$F$157,"还没测") -> 0 | G14: =COUNTIFS(测试清单!$B$6:$B$157,A14,测试清单!$F$6:$F$157,"不适用") -> 0 | H14: =IF(B14-G14=0,"不适用",(C14+D14)/(B14-G14)) -> 0.3
A15: 飞行计划 | B15: =COUNTIF(测试清单!$B$6:$B$157,A15) -> 10 | C15: =COUNTIFS(测试清单!$B$6:$B$157,A15,测试清单!$F$6:$F$157,"通过") -> 4 | D15: =COUNTIFS(测试清单!$B$6:$B$157,A15,测试清单!$F$6:$F$157,"有问题") -> 0 | E15: =COUNTIFS(测试清单!$B$6:$B$157,A15,测试清单!$F$6:$F$157,"暂时测不了") -> 6 | F15: =COUNTIFS(测试清单!$B$6:$B$157,A15,测试清单!$F$6:$F$157,"还没测") -> 0 | G15: =COUNTIFS(测试清单!$B$6:$B$157,A15,测试清单!$F$6:$F$157,"不适用") -> 0 | H15: =IF(B15-G15=0,"不适用",(C15+D15)/(B15-G15)) -> 0.4
A16: 合法性研判 | B16: =COUNTIF(测试清单!$B$6:$B$157,A16) -> 12 | C16: =COUNTIFS(测试清单!$B$6:$B$157,A16,测试清单!$F$6:$F$157,"通过") -> 5 | D16: =COUNTIFS(测试清单!$B$6:$B$157,A16,测试清单!$F$6:$F$157,"有问题") -> 1 | E16: =COUNTIFS(测试清单!$B$6:$B$157,A16,测试清单!$F$6:$F$157,"暂时测不了") -> 6 | F16: =COUNTIFS(测试清单!$B$6:$B$157,A16,测试清单!$F$6:$F$157,"还没测") -> 0 | G16: =COUNTIFS(测试清单!$B$6:$B$157,A16,测试清单!$F$6:$F$157,"不适用") -> 0 | H16: =IF(B16-G16=0,"不适用",(C16+D16)/(B16-G16)) -> 0.5
A17: 空域管理 | B17: =COUNTIF(测试清单!$B$6:$B$157,A17) -> 6 | C17: =COUNTIFS(测试清单!$B$6:$B$157,A17,测试清单!$F$6:$F$157,"通过") -> 1 | D17: =COUNTIFS(测试清单!$B$6:$B$157,A17,测试清单!$F$6:$F$157,"有问题") -> 0 | E17: =COUNTIFS(测试清单!$B$6:$B$157,A17,测试清单!$F$6:$F$157,"暂时测不了") -> 5 | F17: =COUNTIFS(测试清单!$B$6:$B$157,A17,测试清单!$F$6:$F$157,"还没测") -> 0 | G17: =COUNTIFS(测试清单!$B$6:$B$157,A17,测试清单!$F$6:$F$157,"不适用") -> 0 | H17: =IF(B17-G17=0,"不适用",(C17+D17)/(B17-G17)) -> 0.16666667
A18: 风险核验和通知上级 | B18: =COUNTIF(测试清单!$B$6:$B$157,A18) -> 6 | C18: =COUNTIFS(测试清单!$B$6:$B$157,A18,测试清单!$F$6:$F$157,"通过") -> 0 | D18: =COUNTIFS(测试清单!$B$6:$B$157,A18,测试清单!$F$6:$F$157,"有问题") -> 0 | E18: =COUNTIFS(测试清单!$B$6:$B$157,A18,测试清单!$F$6:$F$157,"暂时测不了") -> 6 | F18: =COUNTIFS(测试清单!$B$6:$B$157,A18,测试清单!$F$6:$F$157,"还没测") -> 0 | G18: =COUNTIFS(测试清单!$B$6:$B$157,A18,测试清单!$F$6:$F$157,"不适用") -> 0 | H18: =IF(B18-G18=0,"不适用",(C18+D18)/(B18-G18)) -> 0
A19: 告警事件 | B19: =COUNTIF(测试清单!$B$6:$B$157,A19) -> 9 | C19: =COUNTIFS(测试清单!$B$6:$B$157,A19,测试清单!$F$6:$F$157,"通过") -> 5 | D19: =COUNTIFS(测试清单!$B$6:$B$157,A19,测试清单!$F$6:$F$157,"有问题") -> 0 | E19: =COUNTIFS(测试清单!$B$6:$B$157,A19,测试清单!$F$6:$F$157,"暂时测不了") -> 4 | F19: =COUNTIFS(测试清单!$B$6:$B$157,A19,测试清单!$F$6:$F$157,"还没测") -> 0 | G19: =COUNTIFS(测试清单!$B$6:$B$157,A19,测试清单!$F$6:$F$157,"不适用") -> 0 | H19: =IF(B19-G19=0,"不适用",(C19+D19)/(B19-G19)) -> 0.55555556
A20: 飞手短信和电话 | B20: =COUNTIF(测试清单!$B$6:$B$157,A20) -> 14 | C20: =COUNTIFS(测试清单!$B$6:$B$157,A20,测试清单!$F$6:$F$157,"通过") -> 1 | D20: =COUNTIFS(测试清单!$B$6:$B$157,A20,测试清单!$F$6:$F$157,"有问题") -> 0 | E20: =COUNTIFS(测试清单!$B$6:$B$157,A20,测试清单!$F$6:$F$157,"暂时测不了") -> 13 | F20: =COUNTIFS(测试清单!$B$6:$B$157,A20,测试清单!$F$6:$F$157,"还没测") -> 0 | G20: =COUNTIFS(测试清单!$B$6:$B$157,A20,测试清单!$F$6:$F$157,"不适用") -> 0 | H20: =IF(B20-G20=0,"不适用",(C20+D20)/(B20-G20)) -> 0.071428571
A21: 反制申请 审批 执行和急停 | B21: =COUNTIF(测试清单!$B$6:$B$157,A21) -> 18 | C21: =COUNTIFS(测试清单!$B$6:$B$157,A21,测试清单!$F$6:$F$157,"通过") -> 1 | D21: =COUNTIFS(测试清单!$B$6:$B$157,A21,测试清单!$F$6:$F$157,"有问题") -> 0 | E21: =COUNTIFS(测试清单!$B$6:$B$157,A21,测试清单!$F$6:$F$157,"暂时测不了") -> 17 | F21: =COUNTIFS(测试清单!$B$6:$B$157,A21,测试清单!$F$6:$F$157,"还没测") -> 0 | G21: =COUNTIFS(测试清单!$B$6:$B$157,A21,测试清单!$F$6:$F$157,"不适用") -> 0 | H21: =IF(B21-G21=0,"不适用",(C21+D21)/(B21-G21)) -> 0.055555556
A22: 移送与处罚 | B22: =COUNTIF(测试清单!$B$6:$B$157,A22) -> 9 | C22: =COUNTIFS(测试清单!$B$6:$B$157,A22,测试清单!$F$6:$F$157,"通过") -> 0 | D22: =COUNTIFS(测试清单!$B$6:$B$157,A22,测试清单!$F$6:$F$157,"有问题") -> 0 | E22: =COUNTIFS(测试清单!$B$6:$B$157,A22,测试清单!$F$6:$F$157,"暂时测不了") -> 9 | F22: =COUNTIFS(测试清单!$B$6:$B$157,A22,测试清单!$F$6:$F$157,"还没测") -> 0 | G22: =COUNTIFS(测试清单!$B$6:$B$157,A22,测试清单!$F$6:$F$157,"不适用") -> 0 | H22: =IF(B22-G22=0,"不适用",(C22+D22)/(B22-G22)) -> 0
A23: 证据和视频 | B23: =COUNTIF(测试清单!$B$6:$B$157,A23) -> 8 | C23: =COUNTIFS(测试清单!$B$6:$B$157,A23,测试清单!$F$6:$F$157,"通过") -> 5 | D23: =COUNTIFS(测试清单!$B$6:$B$157,A23,测试清单!$F$6:$F$157,"有问题") -> 2 | E23: =COUNTIFS(测试清单!$B$6:$B$157,A23,测试清单!$F$6:$F$157,"暂时测不了") -> 1 | F23: =COUNTIFS(测试清单!$B$6:$B$157,A23,测试清单!$F$6:$F$157,"还没测") -> 0 | G23: =COUNTIFS(测试清单!$B$6:$B$157,A23,测试清单!$F$6:$F$157,"不适用") -> 0 | H23: =IF(B23-G23=0,"不适用",(C23+D23)/(B23-G23)) -> 0.875
A24: 运行统计 | B24: =COUNTIF(测试清单!$B$6:$B$157,A24) -> 7 | C24: =COUNTIFS(测试清单!$B$6:$B$157,A24,测试清单!$F$6:$F$157,"通过") -> 1 | D24: =COUNTIFS(测试清单!$B$6:$B$157,A24,测试清单!$F$6:$F$157,"有问题") -> 1 | E24: =COUNTIFS(测试清单!$B$6:$B$157,A24,测试清单!$F$6:$F$157,"暂时测不了") -> 4 | F24: =COUNTIFS(测试清单!$B$6:$B$157,A24,测试清单!$F$6:$F$157,"还没测") -> 0 | G24: =COUNTIFS(测试清单!$B$6:$B$157,A24,测试清单!$F$6:$F$157,"不适用") -> 1 | H24: =IF(B24-G24=0,"不适用",(C24+D24)/(B24-G24)) -> 0.33333333
... A28: 规则设置改变后前台会怎样 | B28: =COUNTIF(测试清单!$B$6:$B$157,A28) -> 6 | C28: =COUNTIFS(测试清单!$B$6:$B$157,A28,测试清单!$F$6:$F$157,"通过") -> 0 | D28: =COUNTIFS(测试清单!$B$6:$B$157,A28,测试清单!$F$6:$F$157,"有问题") -> 0 | E28: =COUNTIFS(测试清单!$B$6:$B$157,A28,测试清单!$F$6:$F$157,"暂时测不了") -> 6 | F28: =COUNTIFS(测试清单!$B$6:$B$157,A28,测试清单!$F$6:$F$157,"还没测") -> 0 | G28: =COUNTIFS(测试清单!$B$6:$B$157,A28,测试清单!$F$6:$F$157,"不适用") -> 0 | H28: =IF(B28-G28=0,"不适用",(C28+D28)/(B28-G28)) -> 0
A30: 正式测试前先确认
A31: 短信计时：当前业务约定10秒，代码3秒。按10秒保留验收基准；新口径须留确认记录。
A32: 自动与手动均测试，但自动反制的人为授权依据尚需核对。8种组合均在引擎开启时按类别设置。
A33: 哪些功能已开：自动研判、短信、电话、移送及测试数据录入办法，都要先核对。
A34: “暂时测不了”不算通过。“不适用”要由负责人确认并在实际现象栏写理由。
A35: 已执行比例＝通过和有问题的项数÷适用项数。通过比例＝通过项数÷已执行项数。
A36: 发现越权、错误反制、重复下发、急停假成功、串事件或历史被改写时，必须先处理。
A37: 设备主链分别检查反制与干扰续链；人工处罚交接不以反制完成为前置；鸟群风险另跑独立流程。
A39: 未填结果 | B39: =COUNTBLANK(测试清单!$F$6:$F$157) -> 0 | C39: 无效结果 | D39: =COUNTA(测试清单!$F$6:$F$157)-SUM(B6:F6) -> 0 | E39: 两项应为0；请使用清单中的下拉选项。
A42: 整体流程验收进度
A44: 完整流程数 | B44: 已跑通 | C44: 有问题 | D44: 暂时测不了 | E44: 还没跑 | F44: 进行中 | G44: 未填步骤 | H44: 流程结论
A45: =COUNTA(全流程验收!A6:A41) -> 36 | B45: =COUNTIF(全流程验收!G6:G41,"通过") -> 0 | C45: =COUNTIF(全流程验收!G6:G41,"有问题") -> 1 | D45: =COUNTIF(全流程验收!G6:G41,"暂时测不了") -> 35 | E45: =COUNTIF(全流程验收!G6:G41,"还没测") -> 0 | F45: =COUNTIF(全流程验收!G6:G41,"进行中") -> 0 | G45: =COUNTBLANK(流程步骤记录!G6:G365) -> 0 | H45: =IF(B45=A45,"流程记录齐全","尚未全部跑通") -> 尚未全部跑通
A47: 整体验收包括152项前台模块、48项补充、64项设备运维、36条完整流程及关键口径确认；缺任何必测环节不能算全部完成。
A48: 异常分支以正确阻断和无误动作通过；人工交接与自动交接分开判断。硬件或算法未具备要记录暂时测不了。
A49: 流程标记通过还需每步证据齐全。F14/F15另关联独立子场景；其他组合记录须人工核对各子批次。
A50: 第五轮已实际执行页面、模拟工参和独立自动测试；第四轮历史保留。未修改产品代码，未发送真实短信、电话或反制指令。
A52: 补充测试与整体验收条件
A54: 补充项数 | B54: 记录齐全 | C54: 有问题 | D54: 暂时测不了 | E54: 还没测 | F54: 待补证据 | G54: 流程待补证据 | H54: 模块记录齐全
A55: =COUNTA(补充测试清单!A6:A53) -> 48 | B55: =COUNTIF(补充测试清单!M6:M53,"记录齐全") -> 2 | C55: =COUNTIF(补充测试清单!M6:M53,"有问题") -> 1 | D55: =COUNTIF(补充测试清单!M6:M53,"暂时测不了") -> 45 | E55: =COUNTIF(补充测试清单!M6:M53,"还没测") -> 0 | F55: =COUNTIF(补充测试清单!M6:M53,"待补证据") -> 0 | G55: =COUNTIF(全流程验收!G6:G41,"待补证据") -> 0 | H55: =COUNTIFS(测试清单!F6:F157,"通过",测试清单!G6:G157,"<>",测试清单!H6:H157,"<>",测试清单!I6:I157,"<>",测试清单!J6:J157,"<>")+COUNTIFS(测试清单!F6:F157,"不适用",测试清单!G6:G157,"<>") -> 36
...

Sheet 测试清单
A2: 前台测试清单
D3: 逐行照着做，填写右侧结果和实际现象。可以按模块、优先顺序或结果筛选。
D4: 一行包含多种情况时，全部测完才选“通过”。部分分支已测但仍缺前提的保留阻塞；未完整执行项不计通过。
A5: 编号 | B5: 测试模块 | C5: 优先顺序 | D5: 怎么测 | E5: 怎样才算正常 | F5: 测试结果 | G5: 实际看到什么 | H5: 测试人 | I5: 测试日期 | J5: 截图或证据位置 | K5: 问题编号
A6: 1 | B6: 登录和账号权限 | C6: 必须先测 | D6: 从提供的前台地址登录，再刷新页面 | E6: 进入有权限的页面，登录身份正确，刷新后不白屏 | F6: 通过 | G6: 第五轮：恢复原后端后，前台沿用已登录的超级管理员会话；刷新后身份正确，融合感知、业务导航正常，无白屏。此前有效登录记录保留。 | H6: Codex | I6: 46292 | J6: 第五、六轮证据：front-session-recovered.txt；front-session-recovered.png；reachability.json
A7: 2 | B7: 登录和账号权限 | C7: 重要检查 | D7: 不填账号密码、输错密码、使用停用账号 | E7: 分别给出清楚提示，不让无效账号进入 | F7: 通过 | G7: 第八轮：页面实测空账号提示请输入登录账号、错误口令提示账号或密码错误；正确登录恢复原证据深链。API补测停用专用只读账号时拒绝登录和旧会话，恢复后可登录。 | H7: Codex | I7: 46293 | J7: r8-auth-errors-ui.txt；r8-api-evidence.jsonl | K7: BLOCK-004
A8: 3 | B8: 登录和账号权限 | C8: 必须先测 | D8: 用要求首次改密的账号登录，改密前直接打开业务页面 | E8: 先完成改密；改密后旧密码不能继续使用 | F8: 暂时测不了 | G8: 第八轮：未完成本行全部步骤。浏览器12:04起返回User unavailable；恢复确认后重连仍失败，剩余页面交互无法执行。 接口或隔离测试的局部覆盖不提升为本行整项通过。 | H8: Codex | I8: 46293 | J8: 第八轮报告；r8-current-preconditions.json；r8-browser-recovery.json | K8: BLOCK-004
A9: 4 | B9: 登录和账号权限 | C9: 必须先测 | D9: 退出登录后，按浏览器后退，再刷新旧详情页 | E9: 不能继续读取或操作受保护资料 | F9: 通过 | G9: 第六轮独立标签退出登录后，浏览器后退及刷新均停留登录页，原业务数据不再可见；随后使用现有账号重新登录。 | H9: Codex | I9: 46292 | J9: 第五、六轮证据：r6-logout-history.json；r6-logout-protected.png
A10: 5 | B10: 登录和账号权限 | C10: 必须先测 | D10: 用不同权限账号打开每个业务页面和大屏 | E10: 能进哪些页面，与管理员给的权限一致；知道地址也不能绕过 | F10: 暂时测不了 | G10: 第八轮：未完成本行全部步骤。浏览器12:04起返回User unavailable；恢复确认后重连仍失败，剩余页面交互无法执行。 接口或隔离测试的局部覆盖不提升为本行整项通过。 | H10: Codex | I10: 46293 | J10: 第八轮报告；r8-current-preconditions.json；r8-browser-recovery.json | K10: BLOCK-004
A11: 6 | B11: 登录和账号权限 | C11: 必须先测 | D11: 用只能看甲单位的账号，尝试查看乙单位的列表、详情、文件和视频 | E11: 不能看到、下载或处理乙单位资料；请开发协助检查直接访问也不能绕过 | F11: 不适用 | G11: 第八轮：本用例要求的单位范围账号与当前产品基线不一致：范围配置已撤回，新用户默认ALL。已具备只读及第二操作员账号，但不伪造ASSIGNED范围或以全范围账号冒充范围隔离。 | H11: Codex | I11: 46293 | J11: qa-unblock-account-verification.json；r8-current-preconditions.json | K11: BLOCK-004
A12: 7 | B12: 登录和账号权限 | C12: 必须先测 | D12: 保持页面不关，让管理员撤销权限或停用账号，再尝试操作 | E12: 旧页面不能继续靠原来的权限办事 | F12: 暂时测不了 | G12: 第八轮部分验证，整项未完成：API实测空登录400、错误口令401、停用账号登录拒绝、旧会话不能读取；恢复账号后重新登录读取成功。既有只读账号的用户/角色管理403。页面分支另测。 | H12: Codex | I12: 46293 | J12: r8-api-evidence.jsonl | K12: BLOCK-004
A13: 8 | B13: 登录和账号权限 | C13: 重要检查 | D13: 打开原来的设备、监测、调测、用户、角色、审计页面地址 | E13: 只显示已迁移提示，不重新出现后台管理功能，不自动跳到另一系统 | F13: 通过 | G13: 第五轮逐一打开 devices、monitor、commission、users、roles、archive 六个旧地址；均显示对应迁移提示，地址保留原系统，没有自动跳转或重新出现管理表单。 | H13: Codex | I13: 46292 | J13: 第五、六轮证据：migrated-routes.json
A14: 9 | B14: 登录和账号权限 | C14: 重要检查 | D14: 打开旧风险页、旧首页、旧工作台地址和旧反制授权链接 | E14: 进入当前承接业务的位置；反制授权仍定位同一条记录 | F14: 暂时测不了 | G14: 第八轮：未完成本行全部步骤。浏览器12:04起返回User unavailable；恢复确认后重连仍失败，剩余页面交互无法执行。 接口或隔离测试的局部覆盖不提升为本行整项通过。 | H14: Codex | I14: 46293 | J14: 第八轮报告；r8-current-preconditions.json；r8-browser-recovery.json
A15: 10 | B15: 登录和账号权限 | C15: 必须先测 | D15: 修改登录后的跳转地址，填外部网站、无权限页面或错误地址 | E15: 不被带到陌生网站；无权限仍拦截；错误地址不造成来回跳转 | F15: 暂时测不了 | G15: 第八轮：未完成本行全部步骤。浏览器12:04起返回User unavailable；恢复确认后重连仍失败，剩余页面交互无法执行。 接口或隔离测试的局部覆盖不提升为本行整项通过。 | H15: Codex | I15: 46293 | J15: 第八轮报告；r8-current-preconditions.json；r8-browser-recovery.json | K15: BLOCK-004
A16: 11 | B16: 登录和账号权限 | C16: 重要检查 | D16: 开两个标签页，退出甲账号后登录乙账号，再回旧标签页 | E16: 不混入甲账号的数据；旧页面的失败回复不把乙账号的新登录错误清掉 | F16: 暂时测不了 | G16: 第八轮：未完成本行全部步骤。浏览器12:04起返回User unavailable；恢复确认后重连仍失败，剩余页面交互无法执行。 接口或隔离测试的局部覆盖不提升为本行整项通过。 | H16: Codex | I16: 46293 | J16: 第八轮报告；r8-current-preconditions.json；r8-browser-recovery.json | K16: BLOCK-004
A17: 12 | B17: 登录和账号权限 | C17: 重要检查 | D17: 打开详情后刷新、前进、后退，再试一条不存在的记录 | E17: 能找回正确上下文；不存在时明确提示，不能随便换成另一条 | F17: 有问题 | G17: 原直接刷新及无效ID分支通过，但新增筛选路径复现串上下文：选8e31945d计划→筛选已取消为空→全部状态，详情变29f39fa7，URL仍8e31945d；刷新同一URL又回8e31945d。 | H17: Codex | I17: 46292 | J17: 第五、六轮证据：r6-plan-filter-context-before.json；r6-plan-filter-context-after.json | K17: BUG-006
A18: 13 | B18: 融合感知 | C18: 必须先测 | D18: 用模拟器发送一架无人机的位置，在前台找它 | E18: 列表、地图、详情是同一架；位置、来源和最后上报时间正确 | F18: 通过 | G18: 第八轮：本轮独立MQTT批次sim-0928104253-a184实际发布，经融合、研判生成目标003及关联告警；前台可定位，来源replay、目标编号和事件对应。20分钟批次另完成1670条报文，未以PUBACK代替平台回读。 | H18: Codex | I18: 46293 | J18: r8-scene.json；r8-chain-initial.json；r8-soak-scenario-final.json | K18: BLOCK-005
A19: 14 | B19: 融合感知 | C19: 必须先测 | D19: 让多台设备观察同一目标，再增加一个相邻但不同的目标 | E19: 同一目标按规则合并，不把旁边另一架错误合并；请开发核对识别关联 | F19: 通过 | G19: 第八轮：批次sim-0928104253-a184由雷达和TDOA同时上报首目标，后端目标003的来源链路包含两设备，前台展开多源融合显示雷达/TDOA；相邻两个独立无人机分别产生004/005，未与003合并。 | H19: Codex | I19: 46293 | J19: r8-chain-initial.json; r8-multi-source-ui.txt | K19: BLOCK-005
A20: 15 | B20: 融合感知 | C20: 重要检查 | D20: 查看今天出现过、但已超过5分钟没有更新的目标 | E20: 今天的记录仍保留；但不能说它还在持续实时跟踪；目标多页时数量不漏算 | F20: 暂时测不了 | G20: 第八轮部分验证，整项未完成：今日目标计数保留已停止上报的记录；010/003详情分别显示21/42分钟前最后上报，未冒称最新上报。当前14个今日目标，尚不足目标分页上限，未以小数据量证明跨页不漏数。 | H20: Codex | I20: 46293 | J20: r8-stale-target-ui.txt; r8-multi-source-ui.txt
A21: 16 | B21: 融合感知 | C21: 重要检查 | D21: 请开发准备跨夜数据，检查北京时间零点前后 | E21: “今日目标”按新的一天重新计算，不混入前一天数量 | F21: 暂时测不了 | G21: 第八轮：未完成本行全部步骤。尚无获准时钟控制的浏览器跨夜样本；不能改系统时间影响其他任务。后端边界回归不代替此页面零点验收。 | H21: Codex | I21: 46293 | J21: 第八轮报告；r8-current-preconditions.json；r8-browser-recovery.json
A22: 17 | B22: 融合感知 | C22: 重要检查 | D22: 分别查看正常、离线、有故障、数据失效的设备，再恢复设备 | E22: 地图上的当前异常有提示，恢复后停止；设备类别仍看得清 | F22: 暂时测不了 | G22: 第八轮：未完成本行全部步骤。缺独立健康GOOD的恢复样本或所需TCP/光电协议测试回执；MQTT在线和UNKNOWN不能冒充健康恢复。 浏览器12:04起返回User unavailable；恢复确认后重连仍失败，剩余页面交互无法执行。 | H22: Codex | I22: 46293 | J22: 第八轮报告；r8-current-preconditions.json；r8-browser-recovery.json | K22: BLOCK-006
A23: 18 | B23: 融合感知 | C23: 重要检查 | D23: 在列表选择目标、设备和告警，并打开两侧详情 | E23: 地图选中位置突出、不被挡住，也不能为了显示好看把坐标挪走 | F23: 暂时测不了 | G23: 第八轮：未完成本行全部步骤。浏览器12:04起返回User unavailable；恢复确认后重连仍失败，剩余页面交互无法执行。 接口或隔离测试的局部覆盖不提升为本行整项通过。 | H23: Codex | I23: 46293 | J23: 第八轮报告；r8-current-preconditions.json；r8-browser-recovery.json
A24: 19 | B24: 融合感知 | C24: 必须先测 | D24: 查看有转弯、停留、中断、不同段落的轨迹 | E24: 如实显示，不能把中断前后强行连起来，不能补出不存在的飞行路线 | F24: 暂时测不了 | G24: 第八轮：未完成本行全部步骤。浏览器12:04起返回User unavailable；恢复确认后重连仍失败，剩余页面交互无法执行。 接口或隔离测试的局部覆盖不提升为本行整项通过。 | H24: Codex | I24: 46293 | J24: 第八轮报告；r8-current-preconditions.json；r8-browser-recovery.json | K24: BLOCK-005
A25: 20 | B25: 融合感知 | C25: 重要检查 | D25: 查看按计划飞、偏离计划、尚未飞过和缺少判断依据的路段 | E25: 按计划已飞段绿、偏离段红、未飞计划段灰；缺依据说明未知，不能乱染色 | F25: 暂时测不了 | G25: 第八轮：未完成本行全部步骤。浏览器12:04起返回User unavailable；恢复确认后重连仍失败，剩余页面交互无法执行。 接口或隔离测试的局部覆盖不提升为本行整项通过。 | H25: Codex | I25: 46293 | J25: 第八轮报告；r8-current-preconditions.json；r8-browser-recovery.json | K25: BLOCK-005
A26: 21 | B26: 融合感知 | C26: 重要检查 | D26: 打开视频后换目标、收起视频、离开页面 | E26: 旧画面及时停止；无视频、无权限、模拟画面分别说清楚 | F26: 暂时测不了 | G26: 第八轮：未完成本行全部步骤。缺可用光电任务及真实/获准测试视频流，无法验证任务到播放与串流切换。浏览器12:04起返回User unavailable；恢复确认后重连仍失败，剩余页面交互无法执行。 | H26: Codex | I26: 46293 | J26: 第八轮报告；r8-current-preconditions.json；r8-browser-recovery.json
A27: 22 | B27: 融合感知 | C27: 重要检查 | D27: 请开发模拟地图加载失败、数据读取失败，再恢复 | E27: 失败不能显示成“没有目标”，也不能用假数据填充；恢复后地图不重叠 | F27: 有问题 | G27: 目标接口失败已重复注入：页面短暂错误后仍显示“今日目标0”和“融合感知数据已更新，当前无未查看异常”。解除阻断后实际恢复4目标。底图配置阻断未造成可确认的底图失败，不计该分支通过。 | H27: Codex | I27: 46292 | J27: 第五、六轮证据：targets-failure.txt；targets-failure-recheck.txt；targets-network-failures.json；targets-recovered.txt；targets-failure.png | K27: BUG-003
A28: 23 | B28: 飞行计划 | C28: 必须先测 | D28: 打开一份已录入的计划，核对单位、飞手、无人机编号、起降点、时间和航线 | E28: 与录入资料一致；缺的资料写未提供，不能自己补造 | F28: 通过 | G28: 以模拟器实际提交的独立QA计划逐字段核对：SN、时间、航线ID/版本一致；未提交的单位、飞手、起降点显示未提供，未自行补造。原始请求与接收记录均保存。 | H28: Codex | I28: 46292 | J28: 第五、六轮证据：plan-input-r5.json；input-context-r5.json；plan-preflight-before-start.txt；plan-input-front.png
A29: 24 | B29: 飞行计划 | C29: 重要检查 | D29: 按不同条件查计划，组合筛选、翻页、清空条件 | E29: 条件一起起作用，列表和总数一致；改条件后不会卡在空白的旧页码 | F29: 通过 | G29: 新增3份合法外部输入后共11条，10条/页能翻第2页；改待执行回第1页5条，已取消0条且详情清空，清空筛选恢复11条。当前页面仅提供状态条件；筛选后的URL上下文问题另记BUG-006。 | H29: Codex | I29: 46292 | J29: 第五、六轮证据：r6-pagination-plan-inputs.json；r6-plans-page2.txt；r6-plans-filter-reset.txt；r6-plans-empty-filter.txt；r6-plans-all-restored.txt
A30: 25 | B30: 飞行计划 | C30: 重要检查 | D30: 选择不同计划查看航线，再关掉详情 | E30: 每份计划对应自己的航线；选择和筛选不混乱；轨迹颜色保持一致 | F30: 暂时测不了 | G30: 第八轮：未完成本行全部步骤。浏览器12:04起返回User unavailable；恢复确认后重连仍失败，剩余页面交互无法执行。 接口或隔离测试的局部覆盖不提升为本行整项通过。 | H30: Codex | I30: 46293 | J30: 第八轮报告；r8-current-preconditions.json；r8-browser-recovery.json
A31: 26 | B31: 飞行计划 | C31: 必须先测 | D31: 计划到时间却没发现无人机，分别检查设备正常、异常、资料不足 | E31: 分清“设备异常”“可能没起飞”“目前不能确认”，不能一律认定未起飞 | F31: 暂时测不了 | G31: 第八轮部分验证，整项未完成：页面重新检查成功，附近离线设备与状态未知设备明确区分，无附近设备时提示暂不能判断起飞，未把无记录当安全；覆盖不足/正常等分支由隔离数据库用例补充。 | H31: Codex | I31: 46293 | J31: r8-plan-device-check.txt | K31: BLOCK-006
A32: 27 | B32: 飞行计划 | C32: 重要检查 | D32: 在起飞时间之前查看设备检查 | E32: 可以查看检查情况，不能提前当成“到时未起飞”去通知 | F32: 通过 | G32: 20:18查看20:22:51起飞的QA计划并重新检查，显示“起飞前·周边设备检查”“计划还没执行”；无可检查设备时不提前作未起飞通知。 | H32: Codex | I32: 46292 | J32: 第五、六轮证据：plan-preflight-before-start.txt；plan-input-front.png
A33: 28 | B33: 飞行计划 | C33: 必须先测 | D33: 对真实测试异常发出设备异常通知，再快速重复点击 | E33: 后台能找到对应处理事项；不能多建同一事项；通知完不等于设备已修好 | F33: 暂时测不了 | G33: 第八轮：未完成本行全部步骤。缺独立健康GOOD的恢复样本或所需TCP/光电协议测试回执；MQTT在线和UNKNOWN不能冒充健康恢复。 浏览器12:04起返回User unavailable；恢复确认后重连仍失败，剩余页面交互无法执行。 | H33: Codex | I33: 46293 | J33: 第八轮报告；r8-current-preconditions.json；r8-browser-recovery.json | K33: BLOCK-005
A34: 29 | B34: 飞行计划 | C34: 重要检查 | D34: 查看完全覆盖、部分覆盖、不覆盖计划飞行时间的天气预报，以及缺计划时间的情况 | E34: 只展示与计划时间重合的部分；没覆盖和缺时间分别说明 | F34: 暂时测不了 | G34: 第八轮部分验证，整项未完成：已补齐正式模拟接口数据：完整覆盖显示60分钟、部分覆盖仅显示15分钟重合段，无覆盖明确提示未覆盖；输入契约要求起止时间，现有合法入口无法建立缺时间计划，该分支仅代码检查，未标全通过。 | H34: Codex | I34: 46293 | J34: r8-weather-scenarios.json; r8-weather-partial-ui.txt; r8-weather-next-ui.txt; r8-weather-none-ui.txt
A35: 30 | B35: 飞行计划 | C35: 重要检查 | D35: 打开有覆盖但时段已经结束的预报，再切页回来 | E35: 按现有要求正常保留发布时间和时段，不恢复已取消的“预报过期”提示和到期刷新 | F35: 通过 | G35: 第八轮：通过正式本地接口输入已结束的09:33至10:33模拟预报；天气页仍显示原发布时间08:33和完整时段，没有恢复已撤销的过期提示。 | H35: Codex | I35: 46293 | J35: r8-weather-scenarios.json; r8-weather-expired-ui.txt
A36: 31 | B36: 飞行计划 | C36: 必须先测 | D36: 查看“本计划当前风险”，加入持续风险、已解除风险、已通知但未解除风险和待确认情况 | E36: 当前数量与当前列表一致；已通知仍可能是当前风险；待确认单独说明；历史保留 | F36: 暂时测不了 | G36: 第八轮部分验证，整项未完成：实际SPACE_OBJECT鸟类风险核实并提交通知后仍可在本计划风险接口读取；停止上报后current_status=UNKNOWN、uncertain_total=1，未当解除。尚缺气象风险有效期解除及持续风险的页面组合，浏览器断连。 | H36: Codex | I36: 46293 | J36: r8-risk-final.json；r8-risk-handoff.json | K36: BLOCK-005
A37: 32 | B37: 飞行计划 | C37: 重要检查 | D37: 快速切换同名的不同计划，再进入研判或证据 | E37: 不串天气、风险或证据；完成、取消计划按当前规则展示，不拿上一份内容顶上 | F37: 暂时测不了 | G37: 第八轮：未完成本行全部步骤。浏览器12:04起返回User unavailable；恢复确认后重连仍失败，剩余页面交互无法执行。 接口或隔离测试的局部覆盖不提升为本行整项通过。 | H37: Codex | I37: 46293 | J37: 第八轮报告；r8-current-preconditions.json；r8-browser-recovery.json | K37: BLOCK-005 / BUG-002
A38: 33 | B38: 合法性研判 | C38: 必须先测 | D38: 首次打开页面，对照各类待处理记录 | E38: 默认显示“待处理”；确实需要处理的记录不漏，列表、翻页和统计一致 | F38: 暂时测不了 | G38: 第八轮：未完成本行全部步骤。浏览器12:04起返回User unavailable；恢复确认后重连仍失败，剩余页面交互无法执行。 接口或隔离测试的局部覆盖不提升为本行整项通过。 | H38: Codex | I38: 46293 | J38: 第八轮报告；r8-current-preconditions.json；r8-browser-recovery.json | K38: BLOCK-005
A39: 34 | B39: 合法性研判 | C39: 必须先测 | D39: 准备无人机、鸟、气球、风筝和未知目标，再尝试列表和直接链接 | E39: 这个页面只承接明确识别为无人机的研判；没有计划的无人机仍可保留 | F39: 暂时测不了 | G39: 第八轮部分验证，整项未完成：已实测UAV、BIRD、识别中255、UNKNOWN0与REMOTE_CONTROLLER100。非UAV均未进入UAV研判；鸟类另走风险链。气球/风筝需可追溯算法分类样本，当前模拟器非UAV统一发40，不能用改标签冒充。页面直接深链分支因浏览器断连未完成。 | H39: Codex | I39: 46293 | J39: r8-protocol-types-result.json；r8-bird-evaluation.json；r8-risk-final.json | K39: BLOCK-005
A40: 35 | B40: 合法性研判 | C40: 重要检查 | D40: 切换“核实位置”，再叠加其他筛选 | E40: 按当前研判是否关联告警筛选；不能把没权限查看告警误认成没有告警 | F40: 暂时测不了 | G40: 第八轮部分验证，整项未完成：接口实测有告警3/无告警8合计11；待复核10、已确认1、已驳回0、已改判0，列表范围正确。页面已查核实位置；多条件组合和全部状态点击未完整完成，浏览器断连。 | H40: Codex | I40: 46293 | J40: r8-legality-filter-api.json；r8-review-location-legality.txt | K40: BLOCK-005
A41: 36 | B41: 合法性研判 | C41: 必须先测 | D41: 分别打开依据充分、可以明确判为合法和非法的记录 | E41: 两种明确结论都不强行要求再人工确认；不能只看风险分数来判断可靠程度 | F41: 暂时测不了 | G41: 第八轮：未完成本行全部步骤。浏览器12:04起返回User unavailable；恢复确认后重连仍失败，剩余页面交互无法执行。 接口或隔离测试的局部覆盖不提升为本行整项通过。 | H41: Codex | I41: 46293 | J41: 第八轮报告；r8-current-preconditions.json；r8-browser-recovery.json | K41: BLOCK-005
...

Sheet 准备与流程
A2: 测试准备与操作说明
B3: 完整安排、六个操作示例、误判提醒和验收要求均在本页。
A5: 事项 | B5: 怎么准备或怎么做 | C5: 补充说明
A6: 阅读说明 | B6: 这份文档给实际使用系统、负责测试和参与验收的人看。按下面的顺序操作，检查页面显示和实际处理结果是否一致。每测一项，记下“通过、有问题、暂时测不了、还没测”。
A7: 阅读说明 | B7: 本文是测试安排，下面写的是系统应该怎样表现，不是已经测过的结果。
A8: 一 这次主要测什么
A9: 一 这次主要测什么 | B9: 主要测试业务前台里的登录、融合感知、飞行计划、合法性研判、空域管理、告警事件、反制办理、移送与处罚、证据管理、运行统计和大屏。 本次补充后台设备运维，详见本页下方准备事项、设备运维清单和F31至F36。
A10: 一 这次主要测什么 | B10: 要检查的不只是“按钮能不能点”。还要看：点完后事情有没有真正办成、处理的是不是这架无人机、换个账号能不能看到不该看的数据、出了问题会不会误显示成功。
A11: 打开哪个系统 | B11: 地址 | C11: 测试时用它做什么
A12: 业务前台 | B12: http://localhost:5173/#/login?redirect=/legality | C12: 主要测试对象，按值班人员的日常操作来测
A13: 管理后台 | B13: http://127.0.0.1:5175/login?redirect=/system/roles | C13: 准备账号、设置权限，检查设备、通知和规则配置
A14: 信号模拟器 | B14: http://127.0.0.1:8766/ | C14: 模拟无人机、设备和飞行过程，配合检查前台反应
A15: 一 这次主要测什么 | B15: 模拟测试使用测试设备和测试通知渠道。模拟短信成功，只能说明这次模拟过程正常，不能据此认定真实手机收到了短信；视频和设备动作也一样。
A16: 二 开始之前准备好这些东西
A17: 1 准备能做不同事情的账号
A18: 1 准备能做不同事情的账号 | B18: 不需要把所有操作都放在一个管理员账号里。至少准备能覆盖下面几种情况的账号，哪些账号可以兼用，由管理员按实际权限安排。
A19: 账号能做什么 | B19: 用来检查什么
A20: 只能查看 | B20: 能看资料，但不能核实告警、审批或反制
A21: 能核实告警、申请反制 | B21: 能提交申请，但不能跳过审批
A22: 能审批 | B22: 使用另一账号审批，检查申请和审批是否分开
A23: 能执行已批准的反制 | B23: 只能执行当前允许执行的任务
A24: 被明确授予直接反制权限 | B24: 可以免去逐次审批，但仍要满足设备、范围、时间和证据要求
A25: 只能看某个单位或区域 | B25: 不能看到、下载或处理其他单位、区域的资料
A26: 没有某个页面权限 | B26: 即使知道页面地址，也不能直接进入
A27: 已停用 | B27: 不能继续登录或操作
A28: 没有被授予直接反制权限的管理员 | B28: 检查“管理员”身份是否被错误地当成直接反制许可
A29: 1 准备能做不同事情的账号 | B29: 测试记录里写账号名称和权限，不写密码。
A30: 2 准备几组能互相对应的数据
A31: 2 准备几组能互相对应的数据 | B31: 请开发或环境维护人员配合，通过现有录入、接入和模拟工具准备。不要为了让页面有数据，直接把“执行成功”“已签收”等结果填进数据库。
A32: 准备什么 | B32: 具体例子
A33: 正常飞行 | B33: 有有效飞行计划，沿计划航线飞行的无人机
A34: 异常飞行 | B34: 偏离航线、没有计划、进入测试限飞区域的无人机，各准备一组
A35: 不是无人机的目标 | B35: 鸟、气球、风筝，以及暂时不知道类别的目标
A36: 信息不够的情况 | B36: 没有新位置、资料不全、系统暂时不能确定是否合法
A37: 不同通知结果 | B37: 没有核验飞手、短信可用或不可用、电话可用或不可用、发送失败或结果未知
A38: 不同飞行动作 | B38: 收到短信后离开、收到电话后离开、继续飞、停止上报位置
A39: 不同办理进度 | B39: 待审批、已批准、已驳回、已过期、排队中、执行中、执行失败、已急停
A40: 不同风险情况 | B40: 待核验、待通知、已经通知但风险仍在、已经排除、暂时不能确认
A41: 不同天气资料 | B41: 完全覆盖飞行时间、只覆盖一部分、不覆盖、缺少计划时间
A42: 不同证据 | B42: 图片、视频、文件、飞行轨迹；还要有文件丢失、损坏和无查看权限的情况
...

Sheet 问题记录
A2: 测试问题记录
D3: 本轮只记录，不修改。BUG为已复现问题；OBS为待核实观察；BLOCK为执行条件不足，不混算产品缺陷。
A5: 问题编号 | B5: 检查项编号 | C5: 问题简述 | D5: 怎么操作会出现 | E5: 本来应该怎样 | F5: 实际出现什么 | G5: 严重程度 | H5: 负责人 | I5: 处理进度 | J5: 修复版本和复测情况
A6: BUG-001 | B6: 后台登录页（新增观察项） | C6: 后台多个页面的标签标题出现 undefined | D6: 打开后台登录页；登录后进入设备接入调测，再查看设备管理。 | E6: 各标签标题应显示正确页面名称及平台名称。 | F6: 登录页标题为“登录 - undefined”；登录后调测页仍为“设备接入调测 - undefined”。 | G6: 轻微体验 | H6: 待分配 | I6: 复测通过 | J6: 第五轮浏览器实测登录、设备管理、接入调测及实时监测标签标题正常，无undefined。证据：第五、六轮证据：admin-login-title.png；commission-eo.png；未修改产品代码。
A7: OBS-001 | B7: SIM-01（部分观察） | C7: 模拟器地图缺少3个纹理的控制台告警 | D7: 打开8766信号地图，等待地图加载，读取浏览器控制台。 | E7: 地图所用纹理应能加载，无缺图告警。 | F7: 出现theme-tex-farm、theme-tex-forest、theme-tex-urban could not be loaded。地图加载提示随后消失；尚未判定业务影响。 | G7: 一般问题 | H7: 待分配 | I7: 暂缓并说明 | J7: 第五轮仍有三类缺纹理告警，地图可显示。前台也出现同类警告；尚未确认业务影响。证据：第五、六轮证据：sim-console.json；sim-map.png
A8: BLOCK-001 | B8: AUTH-01、AUTH-02部分、OPS-01部分、F01/F31起步 | C8: 缺少有效测试登录及角色账号 | D8: 按用户提供的三个地址打开系统，检查当前登录状态。 | E8: 使用指定测试账号进入前台、后台及模拟器，再准备隔离批次。 | F8: 三个入口均未登录；截至本轮记录未取得有效账号。空值及虚构账号拒绝已局部检查。 | G8: 影响主要操作 | H8: 测试准备负责人 | I8: 复测通过 | J8: 2026-09-27第二轮已解除：用户提供账号，前台进入合法性页、后台进入设备接入调测。密码不记录在文档中。后续受BLOCK-002影响。
A9: BLOCK-002 | B9: AUTH-01刷新、F01/F31准备、模拟器登录、全部依赖数据库业务 | C9: 测试中途数据库连接中断 | D9: 约18:05登录前台和后台成功；刷新前台，登录模拟器，再读取设备页。核查后端日志和监听端口。 | E9: 数据库持续可用，已登录会话可读取业务资料，模拟器能完成登录。 | F9: 前台提示后端响应超时；模拟器提示无法连接API；后台读取失败。8081仍监听，25432无监听；日志Connection refused、连接池约30秒超时。 | G9: 影响主要操作 | H9: 运行环境负责人 | I9: 复测通过 | J9: 第三轮已恢复原Docker引擎与deploy-db-1、deploy-mosquitto-1。数据库pg_isready通过，health=UP，认证及设备接口200，MQTT新批次成功接收。未清库、未新建替代库。
A10: BLOCK-003 | B10: 前后台页面验收及完整流程 | C10: Codex浏览器站点权限仍拒绝访问 | D10: 前台reload被已保存的localhost:5173禁止设置拦截；后台127.0.0.1:5175访问也被拒绝。 | E10: 用户允许后，浏览器能正常访问测试页面。 | F10: 用户已文字允许继续，但工具仍报告保存的拒绝设置。独立接口测试可执行，页面交互无法执行。 | G10: 影响主要操作 | H10: 浏览器权限设置 | I10: 复测通过 | J10: 第五轮已实际访问5173、5175、8766并完成页面交互，浏览器权限阻塞解除。证据：第五、六轮证据：front-session-recovered.png；weather-onboard.png；inbox-checks.json
A11: BUG-002 | B11: 107及108–114 | C11: 证据台账接口缺失导致页面不可用 | D11: 打开前台证据管理，点击重新读取 | E11: 证据台账与统计可读取 | F11: /api/v1/evidence-ledger无后端映射；页面及统计资源不存在 | G11: 重要功能不可用 | H11: 前后台契约负责人 | I11: 已修复并复测 | J11: 第七轮：补齐evidence-ledger列表/统计/精确记录/材料/CSV。H2+隔离PostgreSQL+认证+目录配置47项通过，package成功，重启后HTTP200；实际页面83条轨迹与166点回放通过。第七轮证据：qa-unblock-full-chain.json；qa-unblock-postrestart.json；qa-unblock-evidence.png；qa-unblock-event-export.csv；qa-unblock-account-verification.json；qa-unblock-package.log。证据目录：C:\Users\Admin（无密码）\.codex\visualizations\2026\09\27\01a0e2a5-9f8d-7261-b23f-0e2b7ef4319e\qa-plan
A12: OBS-002 | B12: 模拟器地图 | C12: 恢复场景名称显示undefined | D12: 恢复模拟器，查看场景名称输入框 | E12: 缺名称应显示空值或合理默认 | F12: 场景名称为字面量undefined；运行时长3分钟也未匹配下拉选项 | G12: 一般体验 | H12: 模拟器负责人 | I12: 待核实 | J12: 第五、六轮证据：sim-map.txt；sim-map.png；规范化场景恢复路径，尚未扩大为所有新建场景问题。
A13: OBS-003 | B13: 后台服务恢复 | C13: 服务不可用提示端口与当前后端不一致 | D13: 后端停止时打开后台设备页 | E13: 提示当前部署的后端地址 | F13: 提示默认8080，本轮实际local服务8081 | G13: 轻微体验 | H13: 管理端负责人 | I13: 待核实 | J13: 第五、六轮证据：admin-service-unavailable.txt；reachability.json
A14: TEST-001 | B14: 前台契约自动测试 | C14: 3项现有测试脚本失败 | D14: 运行6个现有前台契约测试文件 | E14: 测试适配当前源码及Windows换行 | F14: notificationConnectivity旧函数断言；statsApi和targetVideo脚本未兼容CRLF导致import残留 | G14: 测试自动化阻塞 | H14: 前台测试负责人 | I14: 待处理 | J14: 第五、六轮证据：front-contract-tests.log；共8项5通过3失败。未修改脚本，不能当作业务功能通过。
A15: BLOCK-004 | B15: 权限、范围、并发 | C15: 专用权限测试账号未齐 | D15: 核对前后台与模拟器登录 | E15: 提供只读/范围受限/第二操作员等身份 | F15: 用户已明确确认尚无只读、范围受限及第二操作员测试账号；管理员会话有效。 | G15: 阻塞权限验收 | H15: 测试准备负责人 | I15: 部分解除 | J15: 只读及第二操作员已准备，本轮多个写入403与并发冲突已实测；范围受限配置已从当前产品撤回，不再以缺账号笼统阻塞全部权限测试。
A16: BLOCK-005 | B16: 自动组合及F01–F30相关步骤 | C16: 自动引擎和有效业务测试样本未齐 | D16: 查看规则运行提示及业务列表 | E16: 具备合法测试授权、引擎、研判/告警及模拟通知输入 | F16: 引擎明确未启用，当前研判/告警/交接为空；未开启真实反制或发送真实通知 | G16: 阻塞自动链验收 | H16: 测试环境与业务负责人 | I16: 部分解除 | J16: 当前融合/研判/告警及鸟类风险链已实测恢复。剩余是外部通知配置、处罚接收方、设备回执与完整自动授权条件；详见第八轮报告。
... A41: BUG-014 | B41: R29 | C41: 未来观测推进目标最后出现时间及融合轨迹 | D41: 向专用replay识别中目标发重复、旧时刻及未来24小时观测 | E41: 异常时间应隔离，不能把未来点作为当前最新有效位置 | F41: 原轨迹重复未增点；未来观测另入RAW并进入FUSED，last_seen_at推进到次日 | G41: 目标时间可信性 | H41: 融合后端 | I41: 待处理 | J41: r8-time-order-input.json；r8-time-order-result.json；未验证控制资格，不能扩大为自动反制绕过

Sheet 自动手动组合
A2: 自动与手动的8种组合
A3: 8种组合均先保证规则引擎开启且健康，再按类别启停规则。停止整个引擎另测，不能当成切手动。
A5: 组合 | B5: 核实告警 | C5: 发起反制 | D5: 通知处罚部门 | E5: 后台怎样设置 | F5: 前台应该怎样运行 | G5: 每轮要保存的记录
A6: M1 | B6: 手动 | C6: 手动 | D6: 手动 | E6: 引擎开启并健康。 核实类：无启用规则，保留人工处理。 反制类：无启用规则，保留人工处理。 通知处罚类：无启用规则，保留人工处理。 | F6: 人员核实；短信与电话按约定观察。人员按申请审批发起反制。分别核对反制、干扰续链及两次回执。干扰完成后查看冻结交接，由有权人员手动发送处罚通知。送达、签收和办理结果分开。 | G6: 配置截图、规则版本、生效范围和时间、运行健康、本轮账号与设备、模拟批次、目标及告警编号。
A7: M2 | B7: 手动 | C7: 手动 | D7: 自动 | E7: 引擎开启并健康。 核实类：无启用规则，保留人工处理。 反制类：无启用规则，保留人工处理。 通知处罚类：启用规则，全部条件满足。 | F7: 人员核实；短信与电话按约定观察。人员按申请审批发起反制。分别核对反制、干扰续链及两次回执。干扰完成后查看冻结交接，规则满足后自动发送处罚通知。送达、签收和办理结果分开。 | G7: 配置截图、规则版本、生效范围和时间、运行健康、本轮账号与设备、模拟批次、目标及告警编号。
A8: M3 | B8: 手动 | C8: 自动 | D8: 手动 | E8: 引擎开启并健康。 核实类：无启用规则，保留人工处理。 反制类：启用规则，全部条件满足。 通知处罚类：无启用规则，保留人工处理。 须记录允许系统自动执行的有效授权依据。 | F8: 人员核实；短信与电话按约定观察。授权口径确认后系统发起反制。分别核对反制、干扰续链及两次回执。干扰完成后查看冻结交接，由有权人员手动发送处罚通知。送达、签收和办理结果分开。 | G8: 配置截图、规则版本、生效范围和时间、运行健康、本轮账号与设备、模拟批次、目标及告警编号。
A9: M4 | B9: 手动 | C9: 自动 | D9: 自动 | E9: 引擎开启并健康。 核实类：无启用规则，保留人工处理。 反制类：启用规则，全部条件满足。 通知处罚类：启用规则，全部条件满足。 须记录允许系统自动执行的有效授权依据。 | F9: 人员核实；短信与电话按约定观察。授权口径确认后系统发起反制。分别核对反制、干扰续链及两次回执。干扰完成后查看冻结交接，规则满足后自动发送处罚通知。送达、签收和办理结果分开。 | G9: 配置截图、规则版本、生效范围和时间、运行健康、本轮账号与设备、模拟批次、目标及告警编号。
A10: M5 | B10: 自动 | C10: 手动 | D10: 手动 | E10: 引擎开启并健康。 核实类：启用规则，全部条件满足。 反制类：无启用规则，保留人工处理。 通知处罚类：无启用规则，保留人工处理。 | F10: 系统核实；短信与电话按约定观察。人员按申请审批发起反制。分别核对反制、干扰续链及两次回执。干扰完成后查看冻结交接，由有权人员手动发送处罚通知。送达、签收和办理结果分开。 | G10: 配置截图、规则版本、生效范围和时间、运行健康、本轮账号与设备、模拟批次、目标及告警编号。
A11: M6 | B11: 自动 | C11: 手动 | D11: 自动 | E11: 引擎开启并健康。 核实类：启用规则，全部条件满足。 反制类：无启用规则，保留人工处理。 通知处罚类：启用规则，全部条件满足。 | F11: 系统核实；短信与电话按约定观察。人员按申请审批发起反制。分别核对反制、干扰续链及两次回执。干扰完成后查看冻结交接，规则满足后自动发送处罚通知。送达、签收和办理结果分开。 | G11: 配置截图、规则版本、生效范围和时间、运行健康、本轮账号与设备、模拟批次、目标及告警编号。
A12: M7 | B12: 自动 | C12: 自动 | D12: 手动 | E12: 引擎开启并健康。 核实类：启用规则，全部条件满足。 反制类：启用规则，全部条件满足。 通知处罚类：无启用规则，保留人工处理。 须记录允许系统自动执行的有效授权依据。 | F12: 系统核实；短信与电话按约定观察。授权口径确认后系统发起反制。分别核对反制、干扰续链及两次回执。干扰完成后查看冻结交接，由有权人员手动发送处罚通知。送达、签收和办理结果分开。 | G12: 配置截图、规则版本、生效范围和时间、运行健康、本轮账号与设备、模拟批次、目标及告警编号。
A13: M8 | B13: 自动 | C13: 自动 | D13: 自动 | E13: 引擎开启并健康。 核实类：启用规则，全部条件满足。 反制类：启用规则，全部条件满足。 通知处罚类：启用规则，全部条件满足。 须记录允许系统自动执行的有效授权依据。 | F13: 系统核实；短信与电话按约定观察。授权口径确认后系统发起反制。分别核对反制、干扰续链及两次回执。干扰完成后查看冻结交接，规则满足后自动发送处罚通知。送达、签收和办理结果分开。 | G13: 配置截图、规则版本、生效范围和时间、运行健康、本轮账号与设备、模拟批次、目标及告警编号。
A16: 执行提醒
A17: 怎么理解自动 | C17: 本轮要真正启用的，是对应类别的自动执行；不仅是“保存了一条规则”。服务运行正常、规则范围和时段有效、条件满足，才能验证自动动作。
A18: 怎么理解手动 | C18: 手动组合是在引擎开启时停用对应类别的自动规则。关闭整个引擎不保证处罚通知停止自动发送。仍要核对人工权限。
A19: 当前后台入口 | C19: 系统管理 → 规则管理：核实规则、反制规则、通知处罚规则。当前页面通过规则启停及生效设置决定是否自动处理；不假设存在一个控制所有流程的总开关。
A20: 条件不满足时 | C20: 自动规则没有通过，不应误执行。人工入口按原有权限与业务条件决定是否可用，不能因某条规则未通过就一律隐藏，也不能借人工绕过安全条件。
A21: 直接反制另测 | C21: 人员直接反制要求显式权限；系统规则发起采用特殊系统身份。会议要求的人为授权依据须另行核对，不能只凭DIRECT字段认定授权已合格。
A22: 三个开关互不替代 | C22: 关掉自动核实，不等于关掉核实后的飞手短信电话；关掉自动反制，不等于禁止人工反制；通知处罚不等于作出处罚决定。
A23: 本轮先记录时长 | C23: 当前业务约定短信送达后观察10秒，电话播放完成后再10秒；现代码短信3秒，与约定冲突。未有新确认前保留10秒验收基准，详见R16–R19。
A24: 切换什么时候生效 | C24: 切换时记录保存、生效、授权创建、命令排队及实际发送时刻。排队后切手动是否阻断不能假定已实现，按R44核查；切换不是急停。
A25: 数据与通道 | C25: 每种组合使用新批次和独立事件。只用获准的测试资料入口、模拟通知和测试设备；不要在结果表中直接写入成功。
A26: 验收要求 | C26: 8种组合仍需测；正向自动反制必须有明确授权口径。缺少授权依据、渠道或账号填暂时测不了；不能删除该组合，也不能直接标通过。

Sheet 全流程验收
A2: 整体流程验收
A3: 共36条完整流程。F01至F30为前台与业务联动，F31至F36为设备接入、掉线恢复、报修处理、核验失败、并发重试和退役。
A4: “流程结果”自动读取流程步骤记录。任何一步失败、受阻或没有测完，都不能显示整条流程通过。
A5: 流程编号 | B5: 本轮场景 | C5: 配置组合 | D5: 本轮重点怎么做 | E5: 走到哪里才算跑通 | F5: 数据批次及事件编号 | G5: 流程结果 | H5: 负责人 | I5: 执行日期或轮次 | J5: 问题及证据索引
A6: F01 | B6: 手动 / 手动 / 手动 | C6: M1 | D6: 按对应组合跑同一事件：输入、研判、核实、飞手通知、反制、干扰续链、处罚通知、证据和统计。自动授权口径确认后才验正向执行。 | E6: 分别取得反制与干扰两次回执，父子授权可追溯；通知、送达、签收和办理结果正确。无依据的自动授权不能算通过。 | F6: 第八轮：分支证据见J列；未完成整链 | G6: =IF(COUNTIF(流程步骤记录!G6:G15,"有问题")>0,"有问题",IF(COUNTIF(流程步骤记录!G6:G15,"暂时测不了")>0,"暂时测不了",IF(COUNTBLANK(流程步骤记录!G6:G15)>0,"未填结果",IF(COUNTIF(流程步骤记录!G6:G15,"通过")=10,IF(COUNTBLANK(流程步骤记录!H6:L15)>0,"待补证据","通过"),IF(COUNTIF(流程步骤记录!G6:G15,"还没测")=10,"还没测","进行中"))))) -> 暂时测不了 | H6: Codex | I6: 46293 | J6: 第八轮：未完成整项。缺可用反制/干扰测试设备受理及最终回执，自动授权依据仍待确认；既有隔离回归不能替代此现场完整流程。 缺核验飞手及可用短信/电话回执链，未建立满足本分支的独立事件；不伪造送达、播放完成或飞离。 实际处罚接收方列表为空，正式提交返回RECIPIENT_NOT_CONFIGURED；无法验证投递、签收及处罚决定闭环。 证据：第八轮报告；r8-current-preconditions.json；r8-frozen-final-summary.json
A7: F02 | B7: 手动 / 手动 / 自动 | C7: M2 | D7: 按对应组合跑同一事件：输入、研判、核实、飞手通知、反制、干扰续链、处罚通知、证据和统计。自动授权口径确认后才验正向执行。 | E7: 分别取得反制与干扰两次回执，父子授权可追溯；通知、送达、签收和办理结果正确。无依据的自动授权不能算通过。 | F7: 第八轮：分支证据见J列；未完成整链 | G7: =IF(COUNTIF(流程步骤记录!G16:G25,"有问题")>0,"有问题",IF(COUNTIF(流程步骤记录!G16:G25,"暂时测不了")>0,"暂时测不了",IF(COUNTBLANK(流程步骤记录!G16:G25)>0,"未填结果",IF(COUNTIF(流程步骤记录!G16:G25,"通过")=10,IF(COUNTBLANK(流程步骤记录!H16:L25)>0,"待补证据","通过"),IF(COUNTIF(流程步骤记录!G16:G25,"还没测")=10,"还没测","进行中"))))) -> 暂时测不了 | H7: Codex | I7: 46293 | J7: 第八轮：未完成整项。缺可用反制/干扰测试设备受理及最终回执，自动授权依据仍待确认；既有隔离回归不能替代此现场完整流程。 缺核验飞手及可用短信/电话回执链，未建立满足本分支的独立事件；不伪造送达、播放完成或飞离。 实际处罚接收方列表为空，正式提交返回RECIPIENT_NOT_CONFIGURED；无法验证投递、签收及处罚决定闭环。 证据：第八轮报告；r8-current-preconditions.json；r8-frozen-final-summary.json
A8: F03 | B8: 手动 / 自动 / 手动 | C8: M3 | D8: 按对应组合跑同一事件：输入、研判、核实、飞手通知、反制、干扰续链、处罚通知、证据和统计。自动授权口径确认后才验正向执行。 | E8: 分别取得反制与干扰两次回执，父子授权可追溯；通知、送达、签收和办理结果正确。无依据的自动授权不能算通过。 | F8: 第八轮：分支证据见J列；未完成整链 | G8: =IF(COUNTIF(流程步骤记录!G26:G35,"有问题")>0,"有问题",IF(COUNTIF(流程步骤记录!G26:G35,"暂时测不了")>0,"暂时测不了",IF(COUNTBLANK(流程步骤记录!G26:G35)>0,"未填结果",IF(COUNTIF(流程步骤记录!G26:G35,"通过")=10,IF(COUNTBLANK(流程步骤记录!H26:L35)>0,"待补证据","通过"),IF(COUNTIF(流程步骤记录!G26:G35,"还没测")=10,"还没测","进行中"))))) -> 暂时测不了 | H8: Codex | I8: 46293 | J8: 第八轮：未完成整项。缺可用反制/干扰测试设备受理及最终回执，自动授权依据仍待确认；既有隔离回归不能替代此现场完整流程。 缺核验飞手及可用短信/电话回执链，未建立满足本分支的独立事件；不伪造送达、播放完成或飞离。 实际处罚接收方列表为空，正式提交返回RECIPIENT_NOT_CONFIGURED；无法验证投递、签收及处罚决定闭环。 证据：第八轮报告；r8-current-preconditions.json；r8-frozen-final-summary.json
A9: F04 | B9: 手动 / 自动 / 自动 | C9: M4 | D9: 按对应组合跑同一事件：输入、研判、核实、飞手通知、反制、干扰续链、处罚通知、证据和统计。自动授权口径确认后才验正向执行。 | E9: 分别取得反制与干扰两次回执，父子授权可追溯；通知、送达、签收和办理结果正确。无依据的自动授权不能算通过。 | F9: 第八轮：分支证据见J列；未完成整链 | G9: =IF(COUNTIF(流程步骤记录!G36:G45,"有问题")>0,"有问题",IF(COUNTIF(流程步骤记录!G36:G45,"暂时测不了")>0,"暂时测不了",IF(COUNTBLANK(流程步骤记录!G36:G45)>0,"未填结果",IF(COUNTIF(流程步骤记录!G36:G45,"通过")=10,IF(COUNTBLANK(流程步骤记录!H36:L45)>0,"待补证据","通过"),IF(COUNTIF(流程步骤记录!G36:G45,"还没测")=10,"还没测","进行中"))))) -> 暂时测不了 | H9: Codex | I9: 46293 | J9: 第八轮：未完成整项。缺可用反制/干扰测试设备受理及最终回执，自动授权依据仍待确认；既有隔离回归不能替代此现场完整流程。 缺核验飞手及可用短信/电话回执链，未建立满足本分支的独立事件；不伪造送达、播放完成或飞离。 实际处罚接收方列表为空，正式提交返回RECIPIENT_NOT_CONFIGURED；无法验证投递、签收及处罚决定闭环。 证据：第八轮报告；r8-current-preconditions.json；r8-frozen-final-summary.json
A10: F05 | B10: 自动 / 手动 / 手动 | C10: M5 | D10: 按对应组合跑同一事件：输入、研判、核实、飞手通知、反制、干扰续链、处罚通知、证据和统计。自动授权口径确认后才验正向执行。 | E10: 分别取得反制与干扰两次回执，父子授权可追溯；通知、送达、签收和办理结果正确。无依据的自动授权不能算通过。 | F10: 第八轮：分支证据见J列；未完成整链 | G10: =IF(COUNTIF(流程步骤记录!G46:G55,"有问题")>0,"有问题",IF(COUNTIF(流程步骤记录!G46:G55,"暂时测不了")>0,"暂时测不了",IF(COUNTBLANK(流程步骤记录!G46:G55)>0,"未填结果",IF(COUNTIF(流程步骤记录!G46:G55,"通过")=10,IF(COUNTBLANK(流程步骤记录!H46:L55)>0,"待补证据","通过"),IF(COUNTIF(流程步骤记录!G46:G55,"还没测")=10,"还没测","进行中"))))) -> 暂时测不了 | H10: Codex | I10: 46293 | J10: 第八轮：未完成整项。缺可用反制/干扰测试设备受理及最终回执，自动授权依据仍待确认；既有隔离回归不能替代此现场完整流程。 缺核验飞手及可用短信/电话回执链，未建立满足本分支的独立事件；不伪造送达、播放完成或飞离。 实际处罚接收方列表为空，正式提交返回RECIPIENT_NOT_CONFIGURED；无法验证投递、签收及处罚决定闭环。 证据：第八轮报告；r8-current-preconditions.json；r8-frozen-final-summary.json
A11: F06 | B11: 自动 / 手动 / 自动 | C11: M6 | D11: 按对应组合跑同一事件：输入、研判、核实、飞手通知、反制、干扰续链、处罚通知、证据和统计。自动授权口径确认后才验正向执行。 | E11: 分别取得反制与干扰两次回执，父子授权可追溯；通知、送达、签收和办理结果正确。无依据的自动授权不能算通过。 | F11: 第八轮：分支证据见J列；未完成整链 | G11: =IF(COUNTIF(流程步骤记录!G56:G65,"有问题")>0,"有问题",IF(COUNTIF(流程步骤记录!G56:G65,"暂时测不了")>0,"暂时测不了",IF(COUNTBLANK(流程步骤记录!G56:G65)>0,"未填结果",IF(COUNTIF(流程步骤记录!G56:G65,"通过")=10,IF(COUNTBLANK(流程步骤记录!H56:L65)>0,"待补证据","通过"),IF(COUNTIF(流程步骤记录!G56:G65,"还没测")=10,"还没测","进行中"))))) -> 暂时测不了 | H11: Codex | I11: 46293 | J11: 第八轮：未完成整项。缺可用反制/干扰测试设备受理及最终回执，自动授权依据仍待确认；既有隔离回归不能替代此现场完整流程。 缺核验飞手及可用短信/电话回执链，未建立满足本分支的独立事件；不伪造送达、播放完成或飞离。 实际处罚接收方列表为空，正式提交返回RECIPIENT_NOT_CONFIGURED；无法验证投递、签收及处罚决定闭环。 证据：第八轮报告；r8-current-preconditions.json；r8-frozen-final-summary.json
A12: F07 | B12: 自动 / 自动 / 手动 | C12: M7 | D12: 按对应组合跑同一事件：输入、研判、核实、飞手通知、反制、干扰续链、处罚通知、证据和统计。自动授权口径确认后才验正向执行。 | E12: 分别取得反制与干扰两次回执，父子授权可追溯；通知、送达、签收和办理结果正确。无依据的自动授权不能算通过。 | F12: 第八轮：分支证据见J列；未完成整链 | G12: =IF(COUNTIF(流程步骤记录!G66:G75,"有问题")>0,"有问题",IF(COUNTIF(流程步骤记录!G66:G75,"暂时测不了")>0,"暂时测不了",IF(COUNTBLANK(流程步骤记录!G66:G75)>0,"未填结果",IF(COUNTIF(流程步骤记录!G66:G75,"通过")=10,IF(COUNTBLANK(流程步骤记录!H66:L75)>0,"待补证据","通过"),IF(COUNTIF(流程步骤记录!G66:G75,"还没测")=10,"还没测","进行中"))))) -> 暂时测不了 | H12: Codex | I12: 46293 | J12: 第八轮：未完成整项。缺可用反制/干扰测试设备受理及最终回执，自动授权依据仍待确认；既有隔离回归不能替代此现场完整流程。 缺核验飞手及可用短信/电话回执链，未建立满足本分支的独立事件；不伪造送达、播放完成或飞离。 实际处罚接收方列表为空，正式提交返回RECIPIENT_NOT_CONFIGURED；无法验证投递、签收及处罚决定闭环。 证据：第八轮报告；r8-current-preconditions.json；r8-frozen-final-summary.json
A13: F08 | B13: 自动 / 自动 / 自动 | C13: M8 | D13: 按对应组合跑同一事件：输入、研判、核实、飞手通知、反制、干扰续链、处罚通知、证据和统计。自动授权口径确认后才验正向执行。 | E13: 分别取得反制与干扰两次回执，父子授权可追溯；通知、送达、签收和办理结果正确。无依据的自动授权不能算通过。 | F13: 第八轮：分支证据见J列；未完成整链 | G13: =IF(COUNTIF(流程步骤记录!G76:G85,"有问题")>0,"有问题",IF(COUNTIF(流程步骤记录!G76:G85,"暂时测不了")>0,"暂时测不了",IF(COUNTBLANK(流程步骤记录!G76:G85)>0,"未填结果",IF(COUNTIF(流程步骤记录!G76:G85,"通过")=10,IF(COUNTBLANK(流程步骤记录!H76:L85)>0,"待补证据","通过"),IF(COUNTIF(流程步骤记录!G76:G85,"还没测")=10,"还没测","进行中"))))) -> 暂时测不了 | H13: Codex | I13: 46293 | J13: 第八轮：未完成整项。缺可用反制/干扰测试设备受理及最终回执，自动授权依据仍待确认；既有隔离回归不能替代此现场完整流程。 缺核验飞手及可用短信/电话回执链，未建立满足本分支的独立事件；不伪造送达、播放完成或飞离。 实际处罚接收方列表为空，正式提交返回RECIPIENT_NOT_CONFIGURED；无法验证投递、签收及处罚决定闭环。 证据：第八轮报告；r8-current-preconditions.json；r8-frozen-final-summary.json
A14: F09 | B14: 正常飞行不误触发 | C14: M8 | D14: 提供有效计划并持续沿计划飞行。 | E14: 合法依据明确，不产生无故通知、反制或处罚交接。 | F14: 第八轮：分支证据见J列；未完成整链 | G14: =IF(COUNTIF(流程步骤记录!G86:G95,"有问题")>0,"有问题",IF(COUNTIF(流程步骤记录!G86:G95,"暂时测不了")>0,"暂时测不了",IF(COUNTBLANK(流程步骤记录!G86:G95)>0,"未填结果",IF(COUNTIF(流程步骤记录!G86:G95,"通过")=10,IF(COUNTBLANK(流程步骤记录!H86:L95)>0,"待补证据","通过"),IF(COUNTIF(流程步骤记录!G86:G95,"还没测")=10,"还没测","进行中"))))) -> 暂时测不了 | H14: Codex | I14: 46293 | J14: 第八轮：未完成整项。缺可用反制/干扰测试设备受理及最终回执，自动授权依据仍待确认；既有隔离回归不能替代此现场完整流程。 缺核验飞手及可用短信/电话回执链，未建立满足本分支的独立事件；不伪造送达、播放完成或飞离。 实际处罚接收方列表为空，正式提交返回RECIPIENT_NOT_CONFIGURED；无法验证投递、签收及处罚决定闭环。 证据：第八轮报告；r8-current-preconditions.json；r8-frozen-final-summary.json
A15: F10 | B15: 手动核实为误报 | C15: M4 | D15: 待核实事件由人员判误报。 | E15: 后续虽配置自动，仍不能发短信、反制或通知处罚；误报历史保留。 | F15: 第八轮：分支证据见J列；未完成整链 | G15: =IF(COUNTIF(流程步骤记录!G96:G105,"有问题")>0,"有问题",IF(COUNTIF(流程步骤记录!G96:G105,"暂时测不了")>0,"暂时测不了",IF(COUNTBLANK(流程步骤记录!G96:G105)>0,"未填结果",IF(COUNTIF(流程步骤记录!G96:G105,"通过")=10,IF(COUNTBLANK(流程步骤记录!H96:L105)>0,"待补证据","通过"),IF(COUNTIF(流程步骤记录!G96:G105,"还没测")=10,"还没测","进行中"))))) -> 暂时测不了 | H15: Codex | I15: 46293 | J15: 第八轮部分验证，整项未完成：专用待核实告警由管理员在前台判误报，状态和历史正确；M4规则组合与后续自动化不误触发的整链未按独立批次完成。 证据：r8-chain-initial.json；r8-filter-confirmed.txt
A16: F11 | B16: 短信后飞离 | C16: M8 | D16: 短信送达后，目标持续上报飞离区域的有效位置。 | E16: 通知升级及反制停止；保留告警确认和短信记录，不把移送规则当作处罚依据。 | F16: 第八轮：分支证据见J列；未完成整链 | G16: =IF(COUNTIF(流程步骤记录!G106:G115,"有问题")>0,"有问题",IF(COUNTIF(流程步骤记录!G106:G115,"暂时测不了")>0,"暂时测不了",IF(COUNTBLANK(流程步骤记录!G106:G115)>0,"未填结果",IF(COUNTIF(流程步骤记录!G106:G115,"通过")=10,IF(COUNTBLANK(流程步骤记录!H106:L115)>0,"待补证据","通过"),IF(COUNTIF(流程步骤记录!G106:G115,"还没测")=10,"还没测","进行中"))))) -> 暂时测不了 | H16: Codex | I16: 46293 | J16: 第八轮：未完成整项。缺可用反制/干扰测试设备受理及最终回执，自动授权依据仍待确认；既有隔离回归不能替代此现场完整流程。 缺核验飞手及可用短信/电话回执链，未建立满足本分支的独立事件；不伪造送达、播放完成或飞离。 实际处罚接收方列表为空，正式提交返回RECIPIENT_NOT_CONFIGURED；无法验证投递、签收及处罚决定闭环。 证据：第八轮报告；r8-current-preconditions.json；r8-frozen-final-summary.json
A17: F12 | B17: 电话后飞离 | C17: M8 | D17: 短信后仍在域，电话播放完成后飞离并继续上报。 | E17: 第二段观察确认飞离，不继续反制；电话事实保留。 | F17: 第八轮：分支证据见J列；未完成整链 | G17: =IF(COUNTIF(流程步骤记录!G116:G125,"有问题")>0,"有问题",IF(COUNTIF(流程步骤记录!G116:G125,"暂时测不了")>0,"暂时测不了",IF(COUNTBLANK(流程步骤记录!G116:G125)>0,"未填结果",IF(COUNTIF(流程步骤记录!G116:G125,"通过")=10,IF(COUNTBLANK(流程步骤记录!H116:L125)>0,"待补证据","通过"),IF(COUNTIF(流程步骤记录!G116:G125,"还没测")=10,"还没测","进行中"))))) -> 暂时测不了 | H17: Codex | I17: 46293 | J17: 第八轮：未完成整项。缺可用反制/干扰测试设备受理及最终回执，自动授权依据仍待确认；既有隔离回归不能替代此现场完整流程。 缺核验飞手及可用短信/电话回执链，未建立满足本分支的独立事件；不伪造送达、播放完成或飞离。 实际处罚接收方列表为空，正式提交返回RECIPIENT_NOT_CONFIGURED；无法验证投递、签收及处罚决定闭环。 证据：第八轮报告；r8-current-preconditions.json；r8-frozen-final-summary.json
A18: F13 | B18: 通知后停止上报 | C18: M8 | D18: 短信送达后停掉主辅目标位置，设备心跳保留。 | E18: 显示无法确认离开；不误打电话或误反制，不能拿旧位置继续执行。 | F18: 第八轮：分支证据见J列；未完成整链 | G18: =IF(COUNTIF(流程步骤记录!G126:G135,"有问题")>0,"有问题",IF(COUNTIF(流程步骤记录!G126:G135,"暂时测不了")>0,"暂时测不了",IF(COUNTBLANK(流程步骤记录!G126:G135)>0,"未填结果",IF(COUNTIF(流程步骤记录!G126:G135,"通过")=10,IF(COUNTBLANK(流程步骤记录!H126:L135)>0,"待补证据","通过"),IF(COUNTIF(流程步骤记录!G126:G135,"还没测")=10,"还没测","进行中"))))) -> 暂时测不了 | H18: Codex | I18: 46293 | J18: 第八轮：未完成整项。缺可用反制/干扰测试设备受理及最终回执，自动授权依据仍待确认；既有隔离回归不能替代此现场完整流程。 缺核验飞手及可用短信/电话回执链，未建立满足本分支的独立事件；不伪造送达、播放完成或飞离。 实际处罚接收方列表为空，正式提交返回RECIPIENT_NOT_CONFIGURED；无法验证投递、签收及处罚决定闭环。 证据：第八轮报告；r8-current-preconditions.json；r8-frozen-final-summary.json
A19: F14 | B19: 没有核验飞手或渠道不可用 | C19: M8 | D19: F14必须分别完成R40、R41、R42，三个子批次均留证。 | E19: 无飞手/无短信不假造通知；电话不可用仍先短信观察。符合其他条件时才进入后续反制。 | F19: 第八轮：分支证据见J列；未完成整链 | G19: =IF(COUNTIF(流程步骤记录!G136:G145,"有问题")>0,"有问题",IF(COUNTIF(流程步骤记录!G136:G145,"暂时测不了")>0,"暂时测不了",IF(COUNTBLANK(流程步骤记录!G136:G145)>0,"未填结果",IF(COUNTIF(流程步骤记录!G136:G145,"通过")=10,IF(COUNTIFS(补充测试清单!A6:A53,"R40",补充测试清单!M6:M53,"记录齐全")+COUNTIFS(补充测试清单!A6:A53,"R41",补充测试清单!M6:M53,"记录齐全")+COUNTIFS(补充测试清单!A6:A53,"R42",补充测试清单!M6:M53,"记录齐全")<3,"子场景未完成",IF(COUNTBLANK(流程步骤记录!H136:L145)>0,"待补证据","通过")),IF(COUNTIF(流程步骤记录!G136:G145,"还没测")=10,"还没测","进行中"))))) -> 暂时测不了 | H19: Codex | I19: 46293 | J19: 第八轮：未完成整项。缺可用反制/干扰测试设备受理及最终回执，自动授权依据仍待确认；既有隔离回归不能替代此现场完整流程。 缺核验飞手及可用短信/电话回执链，未建立满足本分支的独立事件；不伪造送达、播放完成或飞离。 实际处罚接收方列表为空，正式提交返回RECIPIENT_NOT_CONFIGURED；无法验证投递、签收及处罚决定闭环。 证据：第八轮报告；r8-current-preconditions.json；r8-frozen-final-summary.json
A20: F15 | B20: 自动改手动 | C20: M8→M1 | D20: F15分别完成R43、R44、R45，不能只测一个时机。 | E20: 保存生效后未发送动作停止自动推进，有权人员可接手；已发动作继续核对实际结果。 | F20: 第八轮：分支证据见J列；未完成整链 | G20: =IF(COUNTIF(流程步骤记录!G146:G155,"有问题")>0,"有问题",IF(COUNTIF(流程步骤记录!G146:G155,"暂时测不了")>0,"暂时测不了",IF(COUNTBLANK(流程步骤记录!G146:G155)>0,"未填结果",IF(COUNTIF(流程步骤记录!G146:G155,"通过")=10,IF(COUNTIFS(补充测试清单!A6:A53,"R43",补充测试清单!M6:M53,"记录齐全")+COUNTIFS(补充测试清单!A6:A53,"R44",补充测试清单!M6:M53,"记录齐全")+COUNTIFS(补充测试清单!A6:A53,"R45",补充测试清单!M6:M53,"记录齐全")<3,"子场景未完成",IF(COUNTBLANK(流程步骤记录!H146:L155)>0,"待补证据","通过")),IF(COUNTIF(流程步骤记录!G146:G155,"还没测")=10,"还没测","进行中"))))) -> 暂时测不了 | H20: Codex | I20: 46293 | J20: 第八轮：未完成整项。缺可用反制/干扰测试设备受理及最终回执，自动授权依据仍待确认；既有隔离回归不能替代此现场完整流程。 缺核验飞手及可用短信/电话回执链，未建立满足本分支的独立事件；不伪造送达、播放完成或飞离。 实际处罚接收方列表为空，正式提交返回RECIPIENT_NOT_CONFIGURED；无法验证投递、签收及处罚决定闭环。 证据：第八轮报告；r8-current-preconditions.json；r8-frozen-final-summary.json
A21: F16 | B21: 手动改自动 | C21: M1→M8 | D21: F16须分别记录核实、反制、通知三个切换子批次；全部完成后才汇总。 | E21: 生效后重新检查当前依据和条件，只执行尚未完成的动作；不会重办已完成步骤。 | F21: 第八轮：分支证据见J列；未完成整链 | G21: =IF(COUNTIF(流程步骤记录!G156:G165,"有问题")>0,"有问题",IF(COUNTIF(流程步骤记录!G156:G165,"暂时测不了")>0,"暂时测不了",IF(COUNTBLANK(流程步骤记录!G156:G165)>0,"未填结果",IF(COUNTIF(流程步骤记录!G156:G165,"通过")=10,IF(COUNTBLANK(流程步骤记录!H156:L165)>0,"待补证据","通过"),IF(COUNTIF(流程步骤记录!G156:G165,"还没测")=10,"还没测","进行中"))))) -> 暂时测不了 | H21: Codex | I21: 46293 | J21: 第八轮：未完成整项。缺可用反制/干扰测试设备受理及最终回执，自动授权依据仍待确认；既有隔离回归不能替代此现场完整流程。 缺核验飞手及可用短信/电话回执链，未建立满足本分支的独立事件；不伪造送达、播放完成或飞离。 实际处罚接收方列表为空，正式提交返回RECIPIENT_NOT_CONFIGURED；无法验证投递、签收及处罚决定闭环。 证据：第八轮报告；r8-current-preconditions.json；r8-frozen-final-summary.json
A22: F17 | B22: 自动与人员同时操作 | C22: M8 | D22: F17须分别记录核实、反制、通知三个并发子批次及动作数量。 | E22: 同一事件同一步只产生一次有效动作；冲突有提示，不重复发设备命令或通知。 | F22: 第八轮：分支证据见J列；未完成整链 | G22: =IF(COUNTIF(流程步骤记录!G166:G175,"有问题")>0,"有问题",IF(COUNTIF(流程步骤记录!G166:G175,"暂时测不了")>0,"暂时测不了",IF(COUNTBLANK(流程步骤记录!G166:G175)>0,"未填结果",IF(COUNTIF(流程步骤记录!G166:G175,"通过")=10,IF(COUNTBLANK(流程步骤记录!H166:L175)>0,"待补证据","通过"),IF(COUNTIF(流程步骤记录!G166:G175,"还没测")=10,"还没测","进行中"))))) -> 暂时测不了 | H22: Codex | I22: 46293 | J22: 第八轮：未完成整项。缺可用反制/干扰测试设备受理及最终回执，自动授权依据仍待确认；既有隔离回归不能替代此现场完整流程。 缺核验飞手及可用短信/电话回执链，未建立满足本分支的独立事件；不伪造送达、播放完成或飞离。 实际处罚接收方列表为空，正式提交返回RECIPIENT_NOT_CONFIGURED；无法验证投递、签收及处罚决定闭环。 证据：第八轮报告；r8-current-preconditions.json；r8-frozen-final-summary.json
A23: F18 | B23: 规则不满足后再满足 | C23: M8 | D23: F18须分别记录时间、范围、阈值、持续观测、数据不足五类条件及边界。 | E23: 先停在对应步骤并说明原因，不能自动通过；有效条件满足后只继续一次。 | F23: 第八轮：分支证据见J列；未完成整链 | G23: =IF(COUNTIF(流程步骤记录!G176:G185,"有问题")>0,"有问题",IF(COUNTIF(流程步骤记录!G176:G185,"暂时测不了")>0,"暂时测不了",IF(COUNTBLANK(流程步骤记录!G176:G185)>0,"未填结果",IF(COUNTIF(流程步骤记录!G176:G185,"通过")=10,IF(COUNTBLANK(流程步骤记录!H176:L185)>0,"待补证据","通过"),IF(COUNTIF(流程步骤记录!G176:G185,"还没测")=10,"还没测","进行中"))))) -> 暂时测不了 | H23: Codex | I23: 46293 | J23: 第八轮：未完成整项。缺可用反制/干扰测试设备受理及最终回执，自动授权依据仍待确认；既有隔离回归不能替代此现场完整流程。 缺核验飞手及可用短信/电话回执链，未建立满足本分支的独立事件；不伪造送达、播放完成或飞离。 实际处罚接收方列表为空，正式提交返回RECIPIENT_NOT_CONFIGURED；无法验证投递、签收及处罚决定闭环。 证据：第八轮报告；r8-current-preconditions.json；r8-frozen-final-summary.json
A24: F19 | B24: 服务暂停或断网后恢复 | C24: M8 | D24: 分别模拟执行服务未启用/异常、页面断网、后台处理重启，然后恢复。 | E24: 未启用或异常如实显示；恢复后对账，不重复核实、通知、下发或移送。 | F24: 第八轮：分支证据见J列；未完成整链 | G24: =IF(COUNTIF(流程步骤记录!G186:G195,"有问题")>0,"有问题",IF(COUNTIF(流程步骤记录!G186:G195,"暂时测不了")>0,"暂时测不了",IF(COUNTBLANK(流程步骤记录!G186:G195)>0,"未填结果",IF(COUNTIF(流程步骤记录!G186:G195,"通过")=10,IF(COUNTBLANK(流程步骤记录!H186:L195)>0,"待补证据","通过"),IF(COUNTIF(流程步骤记录!G186:G195,"还没测")=10,"还没测","进行中"))))) -> 暂时测不了 | H24: Codex | I24: 46293 | J24: 第八轮：未完成整项。缺可用反制/干扰测试设备受理及最终回执，自动授权依据仍待确认；既有隔离回归不能替代此现场完整流程。 缺核验飞手及可用短信/电话回执链，未建立满足本分支的独立事件；不伪造送达、播放完成或飞离。 实际处罚接收方列表为空，正式提交返回RECIPIENT_NOT_CONFIGURED；无法验证投递、签收及处罚决定闭环。 证据：第八轮报告；r8-current-preconditions.json；r8-frozen-final-summary.json
A25: F20 | B25: 设备失败并急停核查 | C25: M8 | D25: 分别模拟设备忙、命令失败、结果未知；另运行一批执行中急停。 | E25: 失败不能当成功，不虚构后续移送；急停需要回复与实际停机核查，切换模式不替代急停。 | F25: 第八轮：分支证据见J列；未完成整链 | G25: =IF(COUNTIF(流程步骤记录!G196:G205,"有问题")>0,"有问题",IF(COUNTIF(流程步骤记录!G196:G205,"暂时测不了")>0,"暂时测不了",IF(COUNTBLANK(流程步骤记录!G196:G205)>0,"未填结果",IF(COUNTIF(流程步骤记录!G196:G205,"通过")=10,IF(COUNTBLANK(流程步骤记录!H196:L205)>0,"待补证据","通过"),IF(COUNTIF(流程步骤记录!G196:G205,"还没测")=10,"还没测","进行中"))))) -> 暂时测不了 | H25: Codex | I25: 46293 | J25: 第八轮：未完成整项。缺可用反制/干扰测试设备受理及最终回执，自动授权依据仍待确认；既有隔离回归不能替代此现场完整流程。 缺核验飞手及可用短信/电话回执链，未建立满足本分支的独立事件；不伪造送达、播放完成或飞离。 实际处罚接收方列表为空，正式提交返回RECIPIENT_NOT_CONFIGURED；无法验证投递、签收及处罚决定闭环。 证据：第八轮报告；r8-current-preconditions.json；r8-frozen-final-summary.json
A26: F21 | B26: 排队后资格变化 | C26: M8 | D26: 在排队及续链前，让授权/规则时段到期、观测过期，或取消可执行资格。 | E26: 真正发送前重新检查，不超范围或原授权窗口，不拿以前规则通过的结果继续下发。 | F26: 第八轮：分支证据见J列；未完成整链 | G26: =IF(COUNTIF(流程步骤记录!G206:G215,"有问题")>0,"有问题",IF(COUNTIF(流程步骤记录!G206:G215,"暂时测不了")>0,"暂时测不了",IF(COUNTBLANK(流程步骤记录!G206:G215)>0,"未填结果",IF(COUNTIF(流程步骤记录!G206:G215,"通过")=10,IF(COUNTBLANK(流程步骤记录!H206:L215)>0,"待补证据","通过"),IF(COUNTIF(流程步骤记录!G206:G215,"还没测")=10,"还没测","进行中"))))) -> 暂时测不了 | H26: Codex | I26: 46293 | J26: 第八轮：未完成整项。缺可用反制/干扰测试设备受理及最终回执，自动授权依据仍待确认；既有隔离回归不能替代此现场完整流程。 缺核验飞手及可用短信/电话回执链，未建立满足本分支的独立事件；不伪造送达、播放完成或飞离。 实际处罚接收方列表为空，正式提交返回RECIPIENT_NOT_CONFIGURED；无法验证投递、签收及处罚决定闭环。 证据：第八轮报告；r8-current-preconditions.json；r8-frozen-final-summary.json
A27: F22 | B27: 权限不足人员尝试接手 | C27: M8 | D27: 系统自动条件暂未满足时，用只读和范围受限账号分别操作；再换有权账号。 | E27: 无权人员不能接手，自动模式不授予个人权限；换有权账号也须满足当前业务条件。 | F27: 第八轮：分支证据见J列；未完成整链 | G27: =IF(COUNTIF(流程步骤记录!G216:G225,"有问题")>0,"有问题",IF(COUNTIF(流程步骤记录!G216:G225,"暂时测不了")>0,"暂时测不了",IF(COUNTBLANK(流程步骤记录!G216:G225)>0,"未填结果",IF(COUNTIF(流程步骤记录!G216:G225,"通过")=10,IF(COUNTBLANK(流程步骤记录!H216:L225)>0,"待补证据","通过"),IF(COUNTIF(流程步骤记录!G216:G225,"还没测")=10,"还没测","进行中"))))) -> 暂时测不了 | H27: Codex | I27: 46293 | J27: 第八轮：未完成整项。缺可用反制/干扰测试设备受理及最终回执，自动授权依据仍待确认；既有隔离回归不能替代此现场完整流程。 缺核验飞手及可用短信/电话回执链，未建立满足本分支的独立事件；不伪造送达、播放完成或飞离。 实际处罚接收方列表为空，正式提交返回RECIPIENT_NOT_CONFIGURED；无法验证投递、签收及处罚决定闭环。 证据：第八轮报告；r8-current-preconditions.json；r8-frozen-final-summary.json
A28: F23 | B28: 人员直接反制完整链路 | C28: M1 | D28: 换显式直接授权账号人工发起；另用未授直接权限的管理员尝试。 | E28: 有权者免逐次审批但保留真实操作人；无权者被阻止；设备结果、交接和证据仍完整。 | F28: 第八轮：分支证据见J列；未完成整链 | G28: =IF(COUNTIF(流程步骤记录!G226:G235,"有问题")>0,"有问题",IF(COUNTIF(流程步骤记录!G226:G235,"暂时测不了")>0,"暂时测不了",IF(COUNTBLANK(流程步骤记录!G226:G235)>0,"未填结果",IF(COUNTIF(流程步骤记录!G226:G235,"通过")=10,IF(COUNTBLANK(流程步骤记录!H226:L235)>0,"待补证据","通过"),IF(COUNTIF(流程步骤记录!G226:G235,"还没测")=10,"还没测","进行中"))))) -> 暂时测不了 | H28: Codex | I28: 46293 | J28: 第八轮：未完成整项。缺可用反制/干扰测试设备受理及最终回执，自动授权依据仍待确认；既有隔离回归不能替代此现场完整流程。 缺核验飞手及可用短信/电话回执链，未建立满足本分支的独立事件；不伪造送达、播放完成或飞离。 实际处罚接收方列表为空，正式提交返回RECIPIENT_NOT_CONFIGURED；无法验证投递、签收及处罚决定闭环。 证据：第八轮报告；r8-current-preconditions.json；r8-frozen-final-summary.json
A29: F24 | B29: 处罚通知失败及迟到回执 | C29: M8 | D29: 设备执行完成后模拟移送发送失败、送达未知、签收超时，再补迟到/重复回复。 | E29: 失败与未知明确；先对账再决定补发；只更新同一交接，不重复移送、不把签收当处罚办结。 | F29: 第八轮：分支证据见J列；未完成整链 | G29: =IF(COUNTIF(流程步骤记录!G236:G245,"有问题")>0,"有问题",IF(COUNTIF(流程步骤记录!G236:G245,"暂时测不了")>0,"暂时测不了",IF(COUNTBLANK(流程步骤记录!G236:G245)>0,"未填结果",IF(COUNTIF(流程步骤记录!G236:G245,"通过")=10,IF(COUNTBLANK(流程步骤记录!H236:L245)>0,"待补证据","通过"),IF(COUNTIF(流程步骤记录!G236:G245,"还没测")=10,"还没测","进行中"))))) -> 暂时测不了 | H29: Codex | I29: 46293 | J29: 第八轮：未完成整项。缺可用反制/干扰测试设备受理及最终回执，自动授权依据仍待确认；既有隔离回归不能替代此现场完整流程。 缺核验飞手及可用短信/电话回执链，未建立满足本分支的独立事件；不伪造送达、播放完成或飞离。 实际处罚接收方列表为空，正式提交返回RECIPIENT_NOT_CONFIGURED；无法验证投递、签收及处罚决定闭环。 证据：第八轮报告；r8-current-preconditions.json；r8-frozen-final-summary.json
A30: F25 | B30: 计划天气风险与通知上级 | C30: 独立风险流程 | D30: 录入计划和覆盖其时段的天气，产生有效风险后核验并通知上级；先保持风险，再提供解除依据。 | E30: 天气、计划当前风险、核验、通知送达与签收、解除、历史及统计完整对应；签收不能提前解除风险。 | F30: 第八轮：分支证据见J列；未完成整链 | G30: =IF(COUNTIF(流程步骤记录!G246:G255,"有问题")>0,"有问题",IF(COUNTIF(流程步骤记录!G246:G255,"暂时测不了")>0,"暂时测不了",IF(COUNTBLANK(流程步骤记录!G246:G255)>0,"未填结果",IF(COUNTIF(流程步骤记录!G246:G255,"通过")=10,IF(COUNTBLANK(流程步骤记录!H246:L255)>0,"待补证据","通过"),IF(COUNTIF(流程步骤记录!G246:G255,"还没测")=10,"还没测","进行中"))))) -> 暂时测不了 | H30: Codex | I30: 46293 | J30: 第八轮：未完成整项。已录入四种天气覆盖样本，但天气风险及上级有效回执链未准备齐全。 证据：第八轮报告；r8-current-preconditions.json；r8-frozen-final-summary.json
A31: F26 | B31: 计划未见目标与设备恢复 | C31: 设备异常联动 | D31: 计划到时未发现目标，测试设备异常检查及通知后台；后台处理后分别验证恢复成功和未恢复。 | E31: 前台计划检查、异常通知、后台处理事项和实际设备恢复能对应；已通知或已处理不能冒充恢复。 | F31: 第八轮：分支证据见J列；未完成整链 | G31: =IF(COUNTIF(流程步骤记录!G256:G265,"有问题")>0,"有问题",IF(COUNTIF(流程步骤记录!G256:G265,"暂时测不了")>0,"暂时测不了",IF(COUNTBLANK(流程步骤记录!G256:G265)>0,"未填结果",IF(COUNTIF(流程步骤记录!G256:G265,"通过")=10,IF(COUNTBLANK(流程步骤记录!H256:L265)>0,"待补证据","通过"),IF(COUNTIF(流程步骤记录!G256:G265,"还没测")=10,"还没测","进行中"))))) -> 暂时测不了 | H31: Codex | I31: 46293 | J31: 第八轮：未完成整项。缺独立健康GOOD的恢复样本或所需TCP/光电协议测试回执；MQTT在线和UNKNOWN不能冒充健康恢复。 证据：第八轮报告；r8-current-preconditions.json；r8-frozen-final-summary.json
A32: F27 | B32: 鸟群风险独立闭环 | C32: 风险主线 | D32: 用同一鸟群从发现走到通知、反馈和风险解除；不进入无人机合法性或反制链。 | E32: 风险与通知事实可追溯；有解除依据才解除；旧记录保留。 | F32: 第八轮：分支证据见J列；未完成整链 | G32: =IF(COUNTIF(流程步骤记录!G266:G275,"有问题")>0,"有问题",IF(COUNTIF(流程步骤记录!G266:G275,"暂时测不了")>0,"暂时测不了",IF(COUNTBLANK(流程步骤记录!G266:G275)>0,"未填结果",IF(COUNTIF(流程步骤记录!G266:G275,"通过")=10,IF(COUNTBLANK(流程步骤记录!H266:L275)>0,"待补证据","通过"),IF(COUNTIF(流程步骤记录!G266:G275,"还没测")=10,"还没测","进行中"))))) -> 暂时测不了 | H32: Codex | I32: 46293 | J32: 第八轮部分验证，整项未完成：同一鸟类批次已完成发现、风险生成、核验和通知交接，未进无人机研判；配置未启用阻断实际投递，反馈/解除闭环未完成。 证据：r8-bird-evaluation.json；r8-risk-verification.json；r8-risk-final.json
A33: F28 | B33: 三路融合及降级恢复 | C33: 三路输入 | D33: 融合箱、5G-A、TDOA观察同一目标，制造掉线和补传后回看全链路。 | E33: 统一ID及原始对应完整，降级可见，恢复不触发历史假动作。 | F33: 第八轮：分支证据见J列；未完成整链 | G33: =IF(COUNTIF(流程步骤记录!G276:G285,"有问题")>0,"有问题",IF(COUNTIF(流程步骤记录!G276:G285,"暂时测不了")>0,"暂时测不了",IF(COUNTBLANK(流程步骤记录!G276:G285)>0,"未填结果",IF(COUNTIF(流程步骤记录!G276:G285,"通过")=10,IF(COUNTBLANK(流程步骤记录!H276:L285)>0,"待补证据","通过"),IF(COUNTIF(流程步骤记录!G276:G285,"还没测")=10,"还没测","进行中"))))) -> 暂时测不了 | H33: Codex | I33: 46293 | J33: 第八轮：未完成整项。已实测RADAR/TDOA双源及掉线样本，尚无融合箱/5G-A/TDOA三路完整同批来源及补传链。 证据：第八轮报告；r8-current-preconditions.json；r8-frozen-final-summary.json
A34: F29 | B34: 雷达光电与授权处置 | C34: M1 | D34: 雷达发现、任务式光电跟踪、人工授权、两段设备动作、证据关联。 | E34: 跟踪与授权各有依据，两段回执可追溯，画面和证据不串目标。 | F34: 第八轮：分支证据见J列；未完成整链 | G34: =IF(COUNTIF(流程步骤记录!G286:G295,"有问题")>0,"有问题",IF(COUNTIF(流程步骤记录!G286:G295,"暂时测不了")>0,"暂时测不了",IF(COUNTBLANK(流程步骤记录!G286:G295)>0,"未填结果",IF(COUNTIF(流程步骤记录!G286:G295,"通过")=10,IF(COUNTBLANK(流程步骤记录!H286:L295)>0,"待补证据","通过"),IF(COUNTIF(流程步骤记录!G286:G295,"还没测")=10,"还没测","进行中"))))) -> 暂时测不了 | H34: Codex | I34: 46293 | J34: 第八轮：未完成整项。缺可用反制/干扰测试设备受理及最终回执，自动授权依据仍待确认；既有隔离回归不能替代此现场完整流程。 缺光电跟踪和视频回执。 证据：第八轮报告；r8-current-preconditions.json；r8-frozen-final-summary.json
A35: F30 | B35: 未反制事件的人工交接 | C35: 手动交接 | D35: 已核实事件没有反制记录，也不满足自动干扰完成分支；验证人工交接的实际入口和结果。 | E35: 按当前权限和业务条件办理；前台缺入口要记录，不能用接口联验替代前台通过。 | F35: 第八轮：分支证据见J列；未完成整链 | G35: =IF(COUNTIF(流程步骤记录!G296:G305,"有问题")>0,"有问题",IF(COUNTIF(流程步骤记录!G296:G305,"暂时测不了")>0,"暂时测不了",IF(COUNTBLANK(流程步骤记录!G296:G305)>0,"未填结果",IF(COUNTIF(流程步骤记录!G296:G305,"通过")=10,IF(COUNTBLANK(流程步骤记录!H296:L305)>0,"待补证据","通过"),IF(COUNTIF(流程步骤记录!G296:G305,"还没测")=10,"还没测","进行中"))))) -> 暂时测不了 | H35: Codex | I35: 46293 | J35: 第八轮部分验证，整项未完成：人工交接前提接口已到接收方校验，无反制不是拒绝原因；现无有效处罚接收方，创建返回409且未投递，不能把接口前置检查作为完整前台流程通过。 证据：r8-handoff-recipients.json；r8-api-evidence.jsonl
A36: F31 | B36: 设备接入到前台感知 | C36: 测试TCP设备 | D36: 登记测试雷达，完成调测并发送目标，核对前后台同源。 | E36: 台账、协议任务、原始样本、目标及状态可对应；调测不冒充现场验收。 | F36: 第八轮：分支证据见J列；未完成整链 | G36: =IF(COUNTIF(流程步骤记录!G306:G315,"有问题")>0,"有问题",IF(COUNTIF(流程步骤记录!G306:G315,"暂时测不了")>0,"暂时测不了",IF(COUNTBLANK(流程步骤记录!G306:G315)>0,"未填结果",IF(COUNTIF(流程步骤记录!G306:G315,"通过")=10,IF(COUNTBLANK(流程步骤记录!H306:L315)>0,"待补证据","通过"),IF(COUNTIF(流程步骤记录!G306:G315,"还没测")=10,"还没测","进行中"))))) -> 暂时测不了 | H36: Codex | I36: 46293 | J36: 第八轮：未完成整项。缺独立健康GOOD的恢复样本或所需TCP/光电协议测试回执；MQTT在线和UNKNOWN不能冒充健康恢复。 证据：第八轮报告；r8-current-preconditions.json；r8-frozen-final-summary.json
A37: F32 | B37: MQTT掉线与连接恢复 | C37: MQTT主动上报 | D37: 有效工参上报、超时离线、事件去重、新心跳及恢复核验。 | E37: 连接恢复与整体健康、维护完成分开证明。 | F37: 第八轮：分支证据见J列；未完成整链 | G37: =IF(COUNTIF(流程步骤记录!G316:G325,"有问题")>0,"有问题",IF(COUNTIF(流程步骤记录!G316:G325,"暂时测不了")>0,"暂时测不了",IF(COUNTBLANK(流程步骤记录!G316:G325)>0,"未填结果",IF(COUNTIF(流程步骤记录!G316:G325,"通过")=10,IF(COUNTBLANK(流程步骤记录!H316:L325)>0,"待补证据","通过"),IF(COUNTIF(流程步骤记录!G316:G325,"还没测")=10,"还没测","进行中"))))) -> 暂时测不了 | H37: Codex | I37: 46293 | J37: 第八轮：未完成整项。缺独立健康GOOD的恢复样本或所需TCP/光电协议测试回执；MQTT在线和UNKNOWN不能冒充健康恢复。 证据：第八轮报告；r8-current-preconditions.json；r8-frozen-final-summary.json
A38: F33 | B38: 前台报修到后台完成 | C38: 维护正向闭环 | D38: 前台发现设备异常，后台处理、核验、完成，再回前台确认。 | E38: 同一设备同一事项走通；恢复核验有事实，不以通知或填说明办结。 | F38: 第八轮：分支证据见J列；未完成整链 | G38: =IF(COUNTIF(流程步骤记录!G326:G335,"有问题")>0,"有问题",IF(COUNTIF(流程步骤记录!G326:G335,"暂时测不了")>0,"暂时测不了",IF(COUNTBLANK(流程步骤记录!G326:G335)>0,"未填结果",IF(COUNTIF(流程步骤记录!G326:G335,"通过")=10,IF(COUNTBLANK(流程步骤记录!H326:L335)>0,"待补证据","通过"),IF(COUNTIF(流程步骤记录!G326:G335,"还没测")=10,"还没测","进行中"))))) -> 暂时测不了 | H38: Codex | I38: 46293 | J38: 第八轮：未完成整项。缺独立健康GOOD的恢复样本或所需TCP/光电协议测试回执；MQTT在线和UNKNOWN不能冒充健康恢复。 证据：第八轮报告；r8-current-preconditions.json；r8-frozen-final-summary.json
A39: F34 | B39: 核验失败后重新处理 | C39: 维护异常闭环 | D39: 制造未知、旧状态或再次异常，走失败、恢复处理、再次核验。 | E39: 不凭一次旧PASS办结；旧核验历史保留，恢复后新一轮完成。 | F39: 第八轮：分支证据见J列；未完成整链 | G39: =IF(COUNTIF(流程步骤记录!G336:G345,"有问题")>0,"有问题",IF(COUNTIF(流程步骤记录!G336:G345,"暂时测不了")>0,"暂时测不了",IF(COUNTBLANK(流程步骤记录!G336:G345)>0,"未填结果",IF(COUNTIF(流程步骤记录!G336:G345,"通过")=10,IF(COUNTBLANK(流程步骤记录!H336:L345)>0,"待补证据","通过"),IF(COUNTIF(流程步骤记录!G336:G345,"还没测")=10,"还没测","进行中"))))) -> 暂时测不了 | H39: Codex | I39: 46293 | J39: 第八轮：未完成整项。缺独立健康GOOD的恢复样本或所需TCP/光电协议测试回执；MQTT在线和UNKNOWN不能冒充健康恢复。 证据：第八轮报告；r8-current-preconditions.json；r8-frozen-final-summary.json
A40: F35 | B40: 并发处理与断网重试 | C40: 权限与幂等 | D40: 两个运维人员抢同一任务，提交响应丢失后回查，再撤权验证。 | E40: 状态只推进一次，旧版本不覆盖，重放仍检查当前权限。 | F40: 第八轮：分支证据见J列；未完成整链 | G40: =IF(COUNTIF(流程步骤记录!G346:G355,"有问题")>0,"有问题",IF(COUNTIF(流程步骤记录!G346:G355,"暂时测不了")>0,"暂时测不了",IF(COUNTBLANK(流程步骤记录!G346:G355)>0,"未填结果",IF(COUNTIF(流程步骤记录!G346:G355,"通过")=10,IF(COUNTBLANK(流程步骤记录!H346:L355)>0,"待补证据","通过"),IF(COUNTIF(流程步骤记录!G346:G355,"还没测")=10,"还没测","进行中"))))) -> 暂时测不了 | H40: Codex | I40: 46293 | J40: 第八轮部分验证，整项未完成：两账号抢同一QA维护任务：操作员200、管理员409，1条START，处理人唯一；只读维护写403且无变更。告警响应丢失后回查已另测通过，但不能代替同一维护任务的断网/撤权全流程。 证据：r8-maintenance-concurrency.json；r8-maintenance-readonly.json；r8-response-lost-history.json
A41: F36 | B41: 设备退役与历史保留 | C41: 专用可弃设备 | D41: 从忙碌删除拒绝，到停用空闲后逻辑删除，再查前后台与历史。 | E41: 当前列表清理、旧业务证据保留，设备身份不可重新占用。 | F41: 第八轮：分支证据见J列；未完成整链 | G41: =IF(COUNTIF(流程步骤记录!G356:G365,"有问题")>0,"有问题",IF(COUNTIF(流程步骤记录!G356:G365,"暂时测不了")>0,"暂时测不了",IF(COUNTBLANK(流程步骤记录!G356:G365)>0,"未填结果",IF(COUNTIF(流程步骤记录!G356:G365,"通过")=10,IF(COUNTBLANK(流程步骤记录!H356:L365)>0,"待补证据","通过"),IF(COUNTIF(流程步骤记录!G356:G365,"还没测")=10,"还没测","进行中"))))) -> 有问题 | H41: Codex | I41: 46293 | J41: 第八轮：启用设备删除拒绝、空闲停用后删除和详情隐藏已执行；身份复用被数据库挡住但返回500而非业务说明。执行中设备分支仅隔离回归支持，不能算完整闭环通过。 证据：r8-device-lifecycle-api.json

Sheet 流程步骤记录
A2: 完整流程逐步记录
A3: 共360个步骤。每条流程使用同一可追溯批次；全部步骤通过且H至L记录齐全，才计为流程通过。
A4: 每步填写实际结果、执行人、日期、证据位置及目标/事件编号；准备和收尾步骤可填批次编号。多子批次逐一列出，不用一个通过代替。
A5: 流程编号 | B5: 步骤 | C5: 测试阶段 | D5: 场景 | E5: 怎么做 | F5: 这一步应该看到什么 | G5: 本步结果 | H5: 实际结果及子批次 | I5: 测试人 | J5: 测试日期 | K5: 截图和证据位置 | L5: 目标或事件编号
A6: F01 | B6: 1 | C6: 后台配置与测试准备 | D6: 手动 / 手动 / 手动 | E6: 引擎开启并健康，按本组合逐类启停规则；保存回读版本、范围、时段、通道及授权依据。缺授权口径时记录暂时测不了。 | F6: 实际运行设置与本轮相符；模拟通道可用。无。按组合从头执行。 | G6: 暂时测不了 | H6: 第八轮：本流程本步尚未作为同一事件的完整链路验收。第八轮：未完成整项。缺可用反制/干扰测试设备受理及最终回执，自动授权依据仍待确认；既有隔离回归不能替代此现场完整流程。 缺核验飞手及可用短信/电话回执链，未建立满足本分支的独立事件；不伪造送达、播放完成或飞离。 实际处罚接收方列表为空，正式提交返回RECIPIENT_NOT_CONFIGURED；无法验证投递、签收及处罚决定闭环。 | I6: Codex | J6: 46293 | K6: 第八轮报告；r8-current-preconditions.json；r8-frozen-final-summary.json | L6: 仅引用本轮分支证据，不虚构整链批次
A7: F01 | B7: 2 | C7: 输入数据并识别目标 | D7: 手动 / 手动 / 手动 | E7: 启动新批次，通过获准入口输入计划和目标数据；记录唯一目标、计划和设备编号。 | F7: 能在融合感知查到同一目标，位置、时间和模拟标记正确；发送成功不代替平台已接收。 | G7: 暂时测不了 | H7: 第八轮：本流程本步尚未作为同一事件的完整链路验收。第八轮：未完成整项。缺可用反制/干扰测试设备受理及最终回执，自动授权依据仍待确认；既有隔离回归不能替代此现场完整流程。 缺核验飞手及可用短信/电话回执链，未建立满足本分支的独立事件；不伪造送达、播放完成或飞离。 实际处罚接收方列表为空，正式提交返回RECIPIENT_NOT_CONFIGURED；无法验证投递、签收及处罚决定闭环。 | I7: Codex | J7: 46293 | K7: 第八轮报告；r8-current-preconditions.json；r8-frozen-final-summary.json | L7: 仅引用本轮分支证据，不虚构整链批次
A8: F01 | B8: 3 | C8: 研判和告警关联 | D8: 手动 / 手动 / 手动 | E8: 打开计划、合法性研判和告警，核对同一目标、计划、研判和事件关系。 | F8: 主链准备明确违规且证据充分的事件；各页同一事实。若本轮是合法或误报分支，按该分支正确阻止后续。 | G8: 暂时测不了 | H8: 第八轮：本流程本步尚未作为同一事件的完整链路验收。第八轮：未完成整项。缺可用反制/干扰测试设备受理及最终回执，自动授权依据仍待确认；既有隔离回归不能替代此现场完整流程。 缺核验飞手及可用短信/电话回执链，未建立满足本分支的独立事件；不伪造送达、播放完成或飞离。 实际处罚接收方列表为空，正式提交返回RECIPIENT_NOT_CONFIGURED；无法验证投递、签收及处罚决定闭环。 | I8: Codex | J8: 46293 | K8: 第八轮报告；r8-current-preconditions.json；r8-frozen-final-summary.json | L8: 仅引用本轮分支证据，不虚构整链批次
A9: F01 | B9: 4 | C9: 核实告警 | D9: 手动 / 手动 / 手动 | E9: 用值班账号核实属实；提交前先观察系统是否等待人工。 | F9: 手动模式不自动核实；有权人员提交后记录真实操作人并进入后续阶段。 | G9: 暂时测不了 | H9: 第八轮：本流程本步尚未作为同一事件的完整链路验收。第八轮：未完成整项。缺可用反制/干扰测试设备受理及最终回执，自动授权依据仍待确认；既有隔离回归不能替代此现场完整流程。 缺核验飞手及可用短信/电话回执链，未建立满足本分支的独立事件；不伪造送达、播放完成或飞离。 实际处罚接收方列表为空，正式提交返回RECIPIENT_NOT_CONFIGURED；无法验证投递、签收及处罚决定闭环。 | I9: Codex | J9: 46293 | K9: 第八轮报告；r8-current-preconditions.json；r8-frozen-final-summary.json | L9: 仅引用本轮分支证据，不虚构整链批次
A10: F01 | B10: 5 | C10: 飞手通知和位置观察 | D10: 手动 / 手动 / 手动 | E10: 检查短信发送/送达、观察开始/结束、电话接通/播放与新位置；按本轮条件操作目标。 | F10: 主链持续在域时按已确认时长推进到待反制；短信、电话、飞离各凭自己的真实依据。 | G10: 暂时测不了 | H10: 第八轮：本流程本步尚未作为同一事件的完整链路验收。第八轮：未完成整项。缺可用反制/干扰测试设备受理及最终回执，自动授权依据仍待确认；既有隔离回归不能替代此现场完整流程。 缺核验飞手及可用短信/电话回执链，未建立满足本分支的独立事件；不伪造送达、播放完成或飞离。 实际处罚接收方列表为空，正式提交返回RECIPIENT_NOT_CONFIGURED；无法验证投递、签收及处罚决定闭环。 | I10: Codex | J10: 46293 | K10: 第八轮报告；r8-current-preconditions.json；r8-frozen-final-summary.json | L10: 仅引用本轮分支证据，不虚构整链批次
A11: F01 | B11: 6 | C11: 反制发起和授权 | D11: 手动 / 手动 / 手动 | E11: 等待人工接手，发起申请；换有权审批账号批准，再由执行账号操作测试设备。 | F11: 未人工办理不自动发起；审批、授权有效后才下发；人员权限与设备资格正确。 | G11: 暂时测不了 | H11: 第八轮：本流程本步尚未作为同一事件的完整链路验收。第八轮：未完成整项。缺可用反制/干扰测试设备受理及最终回执，自动授权依据仍待确认；既有隔离回归不能替代此现场完整流程。 缺核验飞手及可用短信/电话回执链，未建立满足本分支的独立事件；不伪造送达、播放完成或飞离。 实际处罚接收方列表为空，正式提交返回RECIPIENT_NOT_CONFIGURED；无法验证投递、签收及处罚决定闭环。 | I11: Codex | J11: 46293 | K11: 第八轮报告；r8-current-preconditions.json；r8-frozen-final-summary.json | L11: 仅引用本轮分支证据，不虚构整链批次
A12: F01 | B12: 7 | C12: 反制与干扰两段结果 | D12: 手动 / 手动 / 手动 | E12: 核对反制父授权、命令和实际回执；完成后核对干扰子授权、父子关系、第二条命令及回执。 | F12: 续链仍需当前证据、有效授权、范围、设备及急停检查。两段分别记结果；干扰失败不把反制完成抹掉，也不能冒充干扰完成。 | G12: 暂时测不了 | H12: 第八轮：本流程本步尚未作为同一事件的完整链路验收。第八轮：未完成整项。缺可用反制/干扰测试设备受理及最终回执，自动授权依据仍待确认；既有隔离回归不能替代此现场完整流程。 缺核验飞手及可用短信/电话回执链，未建立满足本分支的独立事件；不伪造送达、播放完成或飞离。 实际处罚接收方列表为空，正式提交返回RECIPIENT_NOT_CONFIGURED；无法验证投递、签收及处罚决定闭环。 | I12: Codex | J12: 46293 | K12: 第八轮报告；r8-current-preconditions.json；r8-frozen-final-summary.json | L12: 仅引用本轮分支证据，不虚构整链批次
A13: F01 | B13: 8 | C13: 移送送达签收与办理结果 | D13: 手动 / 手动 / 手动 | E13: 干扰完成后查冻结交接。自动通知组合等待规则通过后投递；手动组合在引擎开启且本类停用时由有权人员发送。分别查送达、签收和正式办理结果。 | F13: 通知方式符合配置。发送、送达、签收分开；有正式办理结果才展示，没有就明确尚无结果，不能强行显示处罚完成。 | G13: 暂时测不了 | H13: 第八轮：本流程本步尚未作为同一事件的完整链路验收。第八轮：未完成整项。缺可用反制/干扰测试设备受理及最终回执，自动授权依据仍待确认；既有隔离回归不能替代此现场完整流程。 缺核验飞手及可用短信/电话回执链，未建立满足本分支的独立事件；不伪造送达、播放完成或飞离。 实际处罚接收方列表为空，正式提交返回RECIPIENT_NOT_CONFIGURED；无法验证投递、签收及处罚决定闭环。 | I13: Codex | J13: 46293 | K13: 第八轮报告；r8-current-preconditions.json；r8-frozen-final-summary.json | L13: 仅引用本轮分支证据，不虚构整链批次
A14: F01 | B14: 9 | C14: 证据统计与跨页一致 | D14: 手动 / 手动 / 手动 | E14: 在证据、统计、告警、计划和移送页按同一事件核对。记录所有关联编号和重要时间。 | F14: 原始与冻结材料完整；事件、授权、命令、通知、交接能互相对应；统计按真实事实计数，不把签收当结案。 | G14: 暂时测不了 | H14: 第八轮：本流程本步尚未作为同一事件的完整链路验收。第八轮：未完成整项。缺可用反制/干扰测试设备受理及最终回执，自动授权依据仍待确认；既有隔离回归不能替代此现场完整流程。 缺核验飞手及可用短信/电话回执链，未建立满足本分支的独立事件；不伪造送达、播放完成或飞离。 实际处罚接收方列表为空，正式提交返回RECIPIENT_NOT_CONFIGURED；无法验证投递、签收及处罚决定闭环。 | I14: Codex | J14: 46293 | K14: 第八轮报告；r8-current-preconditions.json；r8-frozen-final-summary.json | L14: 仅引用本轮分支证据，不虚构整链批次
A15: F01 | B15: 10 | C15: 关闭页面与重登复查 | D15: 手动 / 手动 / 手动 | E15: 本轮适用的自动等待阶段关闭页面再打开；结束后刷新、退出重登。核对动作次数并停止模拟。 | F15: 自动办理不依赖页面打开；刷新重登不重复动作；最终结果稳定，历史保留，模拟任务已明确停止。 | G15: 暂时测不了 | H15: 第八轮：本流程本步尚未作为同一事件的完整链路验收。第八轮：未完成整项。缺可用反制/干扰测试设备受理及最终回执，自动授权依据仍待确认；既有隔离回归不能替代此现场完整流程。 缺核验飞手及可用短信/电话回执链，未建立满足本分支的独立事件；不伪造送达、播放完成或飞离。 实际处罚接收方列表为空，正式提交返回RECIPIENT_NOT_CONFIGURED；无法验证投递、签收及处罚决定闭环。 | I15: Codex | J15: 46293 | K15: 第八轮报告；r8-current-preconditions.json；r8-frozen-final-summary.json | L15: 仅引用本轮分支证据，不虚构整链批次
A16: F02 | B16: 1 | C16: 后台配置与测试准备 | D16: 手动 / 手动 / 自动 | E16: 引擎开启并健康，按本组合逐类启停规则；保存回读版本、范围、时段、通道及授权依据。缺授权口径时记录暂时测不了。 | F16: 实际运行设置与本轮相符；模拟通道可用。无。按组合从头执行。 | G16: 暂时测不了 | H16: 第八轮：本流程本步尚未作为同一事件的完整链路验收。第八轮：未完成整项。缺可用反制/干扰测试设备受理及最终回执，自动授权依据仍待确认；既有隔离回归不能替代此现场完整流程。 缺核验飞手及可用短信/电话回执链，未建立满足本分支的独立事件；不伪造送达、播放完成或飞离。 实际处罚接收方列表为空，正式提交返回RECIPIENT_NOT_CONFIGURED；无法验证投递、签收及处罚决定闭环。 | I16: Codex | J16: 46293 | K16: 第八轮报告；r8-current-preconditions.json；r8-frozen-final-summary.json | L16: 仅引用本轮分支证据，不虚构整链批次
A17: F02 | B17: 2 | C17: 输入数据并识别目标 | D17: 手动 / 手动 / 自动 | E17: 启动新批次，通过获准入口输入计划和目标数据；记录唯一目标、计划和设备编号。 | F17: 能在融合感知查到同一目标，位置、时间和模拟标记正确；发送成功不代替平台已接收。 | G17: 暂时测不了 | H17: 第八轮：本流程本步尚未作为同一事件的完整链路验收。第八轮：未完成整项。缺可用反制/干扰测试设备受理及最终回执，自动授权依据仍待确认；既有隔离回归不能替代此现场完整流程。 缺核验飞手及可用短信/电话回执链，未建立满足本分支的独立事件；不伪造送达、播放完成或飞离。 实际处罚接收方列表为空，正式提交返回RECIPIENT_NOT_CONFIGURED；无法验证投递、签收及处罚决定闭环。 | I17: Codex | J17: 46293 | K17: 第八轮报告；r8-current-preconditions.json；r8-frozen-final-summary.json | L17: 仅引用本轮分支证据，不虚构整链批次
